Workbook

Sheet STATIC.0
A1: VERS | B1: Script Ledger | C1: Static 3-column programmatic language ledger
A2: SEXTER | E2: LEXTER | K2: DEXTER
A3: ROWID | B3: VERSID | C3: LEX | D3: DEX | E3: SID | F3: BID | G3: CLO | H3: SER | I3: TEN | J3: PER | K3: CLO | L3: SER | M3: TEN | N3: PER | O3: SID | P3: BID
A4: 0 | B4: =_xlfn.CONCAT($A$1, ".", $A4) -> VERS.0 | C4: =_xlfn.CONCAT(E4,",",F4) -> 0,0 | D4: =_xlfn.CONCAT(O4,",",P4) -> 0,0 | E4: 0 | F4: 0 | H4: class | I4: EJSPiler | L4: extends | M4: Piler | O4: 0 | P4: 0
A5: 1 | B5: =_xlfn.CONCAT($A$1, ".", $A5) -> VERS.1 | C5: =_xlfn.CONCAT(E5,",",F5) -> 1,0 | D5: =_xlfn.CONCAT(O5,",",P5) -> 1,0 | E5: 1 | F5: 0 | G5: {} | I5: #model | O5: 1 | P5: 0
A6: 2 | B6: =_xlfn.CONCAT($A$1, ".", $A6) -> VERS.2 | C6: =_xlfn.CONCAT(E6,",",F6) -> 1,1 | D6: =_xlfn.CONCAT(O6,",",P6) -> 1,1 | E6: 1 | F6: 1 | I6: #renderFileOptions | O6: 1 | P6: 1
A7: 3 | B7: =_xlfn.CONCAT($A$1, ".", $A7) -> VERS.3 | C7: =_xlfn.CONCAT(E7,",",F7) -> 1,2 | D7: =_xlfn.CONCAT(O7,",",P7) -> 1,2 | E7: 1 | F7: 2 | I7: #compileOptions | O7: 1 | P7: 2
A8: 4 | B8: =_xlfn.CONCAT($A$1, ".", $A8) -> VERS.4 | C8: =_xlfn.CONCAT(E8,",",F8) -> 1,3 | D8: =_xlfn.CONCAT(O8,",",P8) -> 1,3 | E8: 1 | F8: 3 | I8: #_root | O8: 1 | P8: 3
A9: 5 | B9: =_xlfn.CONCAT($A$1, ".", $A9) -> VERS.5 | C9: =_xlfn.CONCAT(E9,",",F9) -> 1,4 | D9: =_xlfn.CONCAT(O9,",",P9) -> 2,0 | E9: 1 | F9: 4 | I9: constructor | K9: () | M9: $settings | N9: , | O9: 2 | P9: 0
A10: 6 | B10: =_xlfn.CONCAT($A$1, ".", $A10) -> VERS.6 | C10: =_xlfn.CONCAT(E10,",",F10) -> 2,1 | D10: =_xlfn.CONCAT(O10,",",P10) -> 2,1 | E10: 2 | F10: 1 | M10: $options | N10: , | O10: 2 | P10: 1
A11: 7 | B11: =_xlfn.CONCAT($A$1, ".", $A11) -> VERS.7 | C11: =_xlfn.CONCAT(E11,",",F11) -> 2,2 | D11: =_xlfn.CONCAT(O11,",",P11) -> 2,2 | E11: 2 | F11: 2 | M11: $document | O11: 2 | P11: 2
A12: 8 | B12: =_xlfn.CONCAT($A$1, ".", $A12) -> VERS.8 | C12: =_xlfn.CONCAT(E12,",",F12) -> 2,0 | D12: =_xlfn.CONCAT(O12,",",P12) -> 3,0 | E12: 2 | F12: 0 | G12: {} | I12: super | K12: () | M12: ...arguments | O12: 3 | P12: 0
A13: 9 | B13: =_xlfn.CONCAT($A$1, ".", $A13) -> VERS.9 | C13: =_xlfn.CONCAT(E13,",",F13) -> 1,2 | D13: =_xlfn.CONCAT(O13,",",P13) -> 3,0 | E13: 1 | F13: 2 | H13: get | I13: outputType | K13: () | O13: 3 | P13: 0
A14: 10 | B14: =_xlfn.CONCAT($A$1, ".", $A14) -> VERS.10 | C14: =_xlfn.CONCAT(E14,",",F14) -> 2,0 | D14: =_xlfn.CONCAT(O14,",",P14) -> 2,0 | E14: 2 | F14: 0 | G14: {} | H14: return | I14: this.settings.outputType | O14: 2 | P14: 0
A15: 11 | B15: =_xlfn.CONCAT($A$1, ".", $A15) -> VERS.11 | C15: =_xlfn.CONCAT(E15,",",F15) -> 1,3 | D15: =_xlfn.CONCAT(O15,",",P15) -> 2,0 | E15: 1 | F15: 3 | H15: get | I15: model | K15: () | O15: 2 | P15: 0
A16: 12 | B16: =_xlfn.CONCAT($A$1, ".", $A16) -> VERS.12 | C16: =_xlfn.CONCAT(E16,",",F16) -> 2,0 | D16: =_xlfn.CONCAT(O16,",",P16) -> 3,0 | E16: 2 | F16: 0 | G16: {} | H16: if | K16: () | O16: 3 | P16: 0
A17: 13 | B17: =_xlfn.CONCAT($A$1, ".", $A17) -> VERS.13 | C17: =_xlfn.CONCAT(E17,",",F17) -> 3,0 | D17: =_xlfn.CONCAT(O17,",",P17) -> 3,1 | E17: 3 | F17: 0 | I17: this.#model | J17: !== | M17: undefined | O17: 3 | P17: 1
A18: 14 | B18: =_xlfn.CONCAT($A$1, ".", $A18) -> VERS.14 | C18: =_xlfn.CONCAT(E18,",",F18) -> 3,0 | D18: =_xlfn.CONCAT(O18,",",P18) -> 3,0 | E18: 3 | F18: 0 | G18: {} | H18: return | I18: this.#model | O18: 3 | P18: 0
A19: 15 | B19: =_xlfn.CONCAT($A$1, ".", $A19) -> VERS.15 | C19: =_xlfn.CONCAT(E19,",",F19) -> 2,0 | D19: =_xlfn.CONCAT(O19,",",P19) -> 2,0 | E19: 2 | F19: 0 | I19: this.#model | J19: = | M19: path.join | O19: 2 | P19: 0
A20: 16 | B20: =_xlfn.CONCAT($A$1, ".", $A20) -> VERS.16 | C20: =_xlfn.CONCAT(E20,",",F20) -> 3,0 | D20: =_xlfn.CONCAT(O20,",",P20) -> 3,0 | E20: 3 | F20: 0 | G20: () | I20: this.document.source | J20: , | O20: 3 | P20: 0
A21: 17 | B21: =_xlfn.CONCAT($A$1, ".", $A21) -> VERS.17 | C21: =_xlfn.CONCAT(E21,",",F21) -> 3,1 | D21: =_xlfn.CONCAT(O21,",",P21) -> 3,1 | E21: 3 | F21: 1 | I21: this.settings.model | O21: 3 | P21: 1
A22: 18 | B22: =_xlfn.CONCAT($A$1, ".", $A22) -> VERS.18 | C22: =_xlfn.CONCAT(E22,",",F22) -> 3,2 | D22: =_xlfn.CONCAT(O22,",",P22) -> 3,2 | E22: 3 | F22: 2 | H22: return | I22: this.#model | O22: 3 | P22: 2

Sheet DYNAMIC.0
A1: VERS | B1: Script Ledger | C1: Static 3-column programmatic language ledger
A2: SEXTER | E2: LEXTER | P2: DEXTER
A3: ROWID | B3: VERSID | C3: LEX | D3: DEX | E3: SID | F3: BID | G3: CLO | H3: SER | I3: TEN | O3: PER | P3: CLO | Q3: SER | R3: TEN | S3: PER | T3: SID | U3: BID
A4: 0 | B4: =_xlfn.CONCAT($A$1, ".", $A4) -> VERS.0 | C4: =_xlfn.CONCAT(E4,",",F4) -> 0,0 | D4: =_xlfn.CONCAT(T4,",",U4) -> 0,0 | E4: 0 | F4: 0 | H4: class | I4: EJSPiler | Q4: extends | R4: Piler | T4: 0 | U4: 0
A5: 1 | B5: =_xlfn.CONCAT($A$1, ".", $A5) -> VERS.1 | C5: =_xlfn.CONCAT(E5,",",F5) -> 1,0 | D5: =_xlfn.CONCAT(T5,",",U5) -> 1,0 | E5: 1 | F5: 0 | G5: {} | J5: #model | T5: 1 | U5: 0
A6: 2 | B6: =_xlfn.CONCAT($A$1, ".", $A6) -> VERS.2 | C6: =_xlfn.CONCAT(E6,",",F6) -> 1,1 | D6: =_xlfn.CONCAT(T6,",",U6) -> 1,1 | E6: 1 | F6: 1 | J6: #renderFileOptions | T6: 1 | U6: 1
A7: 3 | B7: =_xlfn.CONCAT($A$1, ".", $A7) -> VERS.3 | C7: =_xlfn.CONCAT(E7,",",F7) -> 1,2 | D7: =_xlfn.CONCAT(T7,",",U7) -> 1,2 | E7: 1 | F7: 2 | J7: #compileOptions | T7: 1 | U7: 2
A8: 4 | B8: =_xlfn.CONCAT($A$1, ".", $A8) -> VERS.4 | C8: =_xlfn.CONCAT(E8,",",F8) -> 1,3 | D8: =_xlfn.CONCAT(T8,",",U8) -> 1,3 | E8: 1 | F8: 3 | J8: #_root | T8: 1 | U8: 3
A9: 5 | B9: =_xlfn.CONCAT($A$1, ".", $A9) -> VERS.5 | C9: =_xlfn.CONCAT(E9,",",F9) -> 1,4 | D9: =_xlfn.CONCAT(T9,",",U9) -> 2,0 | E9: 1 | F9: 4 | J9: constructor | P9: () | R9: $settings | S9: , | T9: 2 | U9: 0
A10: 6 | B10: =_xlfn.CONCAT($A$1, ".", $A10) -> VERS.6 | C10: =_xlfn.CONCAT(E10,",",F10) -> 2,1 | D10: =_xlfn.CONCAT(T10,",",U10) -> 2,1 | E10: 2 | F10: 1 | R10: $options | S10: , | T10: 2 | U10: 1
A11: 7 | B11: =_xlfn.CONCAT($A$1, ".", $A11) -> VERS.7 | C11: =_xlfn.CONCAT(E11,",",F11) -> 2,2 | D11: =_xlfn.CONCAT(T11,",",U11) -> 2,2 | E11: 2 | F11: 2 | R11: $document | T11: 2 | U11: 2
A12: 8 | B12: =_xlfn.CONCAT($A$1, ".", $A12) -> VERS.8 | C12: =_xlfn.CONCAT(E12,",",F12) -> 2,0 | D12: =_xlfn.CONCAT(T12,",",U12) -> 3,0 | E12: 2 | F12: 0 | G12: {} | K12: super | P12: () | R12: ...arguments | T12: 3 | U12: 0
A13: 9 | B13: =_xlfn.CONCAT($A$1, ".", $A13) -> VERS.9 | C13: =_xlfn.CONCAT(E13,",",F13) -> 1,2 | D13: =_xlfn.CONCAT(T13,",",U13) -> 3,0 | E13: 1 | F13: 2 | H13: get | J13: outputType | P13: () | T13: 3 | U13: 0
A14: 10 | B14: =_xlfn.CONCAT($A$1, ".", $A14) -> VERS.10 | C14: =_xlfn.CONCAT(E14,",",F14) -> 2,0 | D14: =_xlfn.CONCAT(T14,",",U14) -> 2,0 | E14: 2 | F14: 0 | G14: {} | H14: return | K14: this.settings.outputType | T14: 2 | U14: 0
A15: 11 | B15: =_xlfn.CONCAT($A$1, ".", $A15) -> VERS.11 | C15: =_xlfn.CONCAT(E15,",",F15) -> 1,3 | D15: =_xlfn.CONCAT(T15,",",U15) -> 2,0 | E15: 1 | F15: 3 | H15: get | J15: model | P15: () | T15: 2 | U15: 0
A16: 12 | B16: =_xlfn.CONCAT($A$1, ".", $A16) -> VERS.12 | C16: =_xlfn.CONCAT(E16,",",F16) -> 2,0 | D16: =_xlfn.CONCAT(T16,",",U16) -> 3,0 | E16: 2 | F16: 0 | G16: {} | H16: if | P16: () | T16: 3 | U16: 0
A17: 13 | B17: =_xlfn.CONCAT($A$1, ".", $A17) -> VERS.13 | C17: =_xlfn.CONCAT(E17,",",F17) -> 3,0 | D17: =_xlfn.CONCAT(T17,",",U17) -> 3,1 | E17: 3 | F17: 0 | I17: this.#model | O17: !== | R17: undefined | T17: 3 | U17: 1
A18: 14 | B18: =_xlfn.CONCAT($A$1, ".", $A18) -> VERS.14 | C18: =_xlfn.CONCAT(E18,",",F18) -> 3,0 | D18: =_xlfn.CONCAT(T18,",",U18) -> 3,0 | E18: 3 | F18: 0 | G18: {} | H18: return | I18: this.#model | T18: 3 | U18: 0
A19: 15 | B19: =_xlfn.CONCAT($A$1, ".", $A19) -> VERS.15 | C19: =_xlfn.CONCAT(E19,",",F19) -> 2,0 | D19: =_xlfn.CONCAT(T19,",",U19) -> 2,0 | E19: 2 | F19: 0 | I19: this.#model | O19: = | R19: path.join | T19: 2 | U19: 0
A20: 16 | B20: =_xlfn.CONCAT($A$1, ".", $A20) -> VERS.16 | C20: =_xlfn.CONCAT(E20,",",F20) -> 3,0 | D20: =_xlfn.CONCAT(T20,",",U20) -> 3,0 | E20: 3 | F20: 0 | G20: () | I20: this.document.source | O20: , | T20: 3 | U20: 0
A21: 17 | B21: =_xlfn.CONCAT($A$1, ".", $A21) -> VERS.17 | C21: =_xlfn.CONCAT(E21,",",F21) -> 3,1 | D21: =_xlfn.CONCAT(T21,",",U21) -> 3,1 | E21: 3 | F21: 1 | I21: this.settings.model | T21: 3 | U21: 1
A22: 18 | B22: =_xlfn.CONCAT($A$1, ".", $A22) -> VERS.18 | C22: =_xlfn.CONCAT(E22,",",F22) -> 3,2 | D22: =_xlfn.CONCAT(T22,",",U22) -> 3,2 | E22: 3 | F22: 2 | H22: return | I22: this.#model | T22: 3 | U22: 2

Sheet DYNAMIC.1
A1: VERS | B1: Script Ledger | C1: Static 3-column programmatic language ledger
A2: SEXTER | C2: LEXTER | L2: DEXTER
A3: ROWID | B3: VERSID | C3: SER | D3: CLO | E3: TEN | K3: PER | L3: SER | M3: CLO | N3: TEN | T3: PER
A4: 0 | B4: =_xlfn.CONCAT($A$1, ".", $A4) -> VERS.0 | C4: class | E4: EJSPiler | L4: extends | N4: Piler
A5: 1 | B5: =_xlfn.CONCAT($A$1, ".", $A5) -> VERS.1 | D5: {} | F5: #model
A6: 2 | B6: =_xlfn.CONCAT($A$1, ".", $A6) -> VERS.2 | F6: #renderFileOptions
A7: 3 | B7: =_xlfn.CONCAT($A$1, ".", $A7) -> VERS.3 | F7: #compileOptions
A8: 4 | B8: =_xlfn.CONCAT($A$1, ".", $A8) -> VERS.4 | F8: #_root
A9: 5 | B9: =_xlfn.CONCAT($A$1, ".", $A9) -> VERS.5 | F9: constructor | M9: () | O9: $settings | T9: ,
A10: 6 | B10: =_xlfn.CONCAT($A$1, ".", $A10) -> VERS.6 | O10: $options | T10: ,
A11: 7 | B11: =_xlfn.CONCAT($A$1, ".", $A11) -> VERS.7 | O11: $document
A12: 8 | B12: =_xlfn.CONCAT($A$1, ".", $A12) -> VERS.8 | D12: {} | G12: super | M12: () | O12: ...arguments
A13: 9 | B13: =_xlfn.CONCAT($A$1, ".", $A13) -> VERS.9 | C13: get | F13: outputType | M13: ()
A14: 10 | B14: =_xlfn.CONCAT($A$1, ".", $A14) -> VERS.10 | D14: {} | L14: return | P14: this.settings.outputType
A15: 11 | B15: =_xlfn.CONCAT($A$1, ".", $A15) -> VERS.11 | C15: get | F15: model | M15: ()
A16: 12 | B16: =_xlfn.CONCAT($A$1, ".", $A16) -> VERS.12 | C16: if | D16: {} | M16: ()
A17: 13 | B17: =_xlfn.CONCAT($A$1, ".", $A17) -> VERS.13 | E17: this.#model | K17: !== | N17: undefined
A18: 14 | B18: =_xlfn.CONCAT($A$1, ".", $A18) -> VERS.14 | C18: return | D18: {} | E18: this.#model
A19: 15 | B19: =_xlfn.CONCAT($A$1, ".", $A19) -> VERS.15 | E19: this.#model | K19: = | N19: path.join
A20: 16 | B20: =_xlfn.CONCAT($A$1, ".", $A20) -> VERS.16 | D20: () | E20: this.document.source | K20: ,
A21: 17 | B21: =_xlfn.CONCAT($A$1, ".", $A21) -> VERS.17 | E21: this.settings.model
A22: 18 | B22: =_xlfn.CONCAT($A$1, ".", $A22) -> VERS.18 | C22: return | E22: this.#model

Sheet DYNAMIC.3
A1: VERS | B1: Script Ledger | C1: Static 3-column programmatic language ledger
A2: SEXTER | E2: LEXTER | P2: DEXTER
A3: ROWID | B3: VERSID | C3: LEX | D3: DEX | E3: SID | F3: BID | G3: SER | H3: CLO | I3: TEN | O3: PER | P3: SER | Q3: CLO | R3: TEN | X3: PER | Y3: SID | Z3: BID
A4: 0 | B4: VERS.0 | C4: 0,0 | D4: 0,0 | E4: 0 | G4: class | I4: EJSPiler | P4: extends | R4: Piler
A5: 1 | B5: VERS.1 | C5: 1,0 | D5: 1,0 | E5: 1 | H5: {} | J5: #model
A6: 2 | B6: VERS.2 | C6: 1,1 | D6: 1,1 | E6: 1 | J6: #renderFileOptions
A7: 3 | B7: VERS.3 | C7: 1,2 | D7: 1,2 | E7: 1 | J7: #compileOptions
A8: 4 | B8: VERS.4 | C8: 1,3 | D8: 1,3 | E8: 1 | J8: #_root
A9: 5 | B9: VERS.5 | C9: 1,4 | D9: 2,0 | E9: 1 | J9: constructor | Q9: () | S9: $settings | X9: , | Y9: 2
A10: 6 | B10: VERS.6 | C10: 2,1 | D10: 2,1 | H10: () | S10: $options | X10: ,
A11: 7 | B11: VERS.7 | C11: 2,2 | D11: 2,2
A12: 8 | B12: VERS.8 | C12: 2,0 | D12: 3,0
A13: 9 | B13: VERS.9 | C13: 1,2 | D13: 3,0
A14: 10 | B14: VERS.10 | C14: 2,0 | D14: 2,0
A15: 11 | B15: VERS.11 | C15: 1,3 | D15: 2,0
A16: 12 | B16: VERS.12 | C16: 2,0 | D16: 3,0
A17: 13 | B17: VERS.13 | C17: 3,0 | D17: 3,1
A18: 14 | B18: VERS.14 | C18: 3,0 | D18: 3,0
A19: 15 | B19: VERS.15 | C19: 2,0 | D19: 2,0
A20: 16 | B20: VERS.16 | C20: 3,0 | D20: 3,0
A21: 17 | B21: VERS.17 | C21: 3,1 | D21: 3,1
A22: 18 | B22: VERS.18 | C22: 3,2 | D22: 3,2
I23: 0 | J23: 1 | K23: 2 | L23: 3 | M23: 4 | N23: 5 | R23: 0 | S23: 1 | T23: 2 | U23: 3 | V23: 4 | W23: 5

Sheet DYNAMIC.4
A1: VERS | B1: Script Ledger | C1: Static 3-column programmatic language ledger
A2: SEXTER | E2: LEXTER | P2: DEXTER
A3: ROWID | B3: VERSID | C3: LEX | D3: DEX | E3: SER | F3: CLO | G3: TEN | M3: PER | N3: SER | O3: CLO | P3: TEN | V3: PER
A4: 0 | B4: VERS.0 | C4: 0,0 | D4: 0,0 | E4: class | G4: EJSPiler | N4: extends | P4: Piler
A5: 1 | B5: VERS.1 | C5: 1,0 | D5: 1,0 | F5: {} | H5: #model
A6: 2 | B6: VERS.2 | C6: 1,1 | D6: 1,1 | H6: #renderFileOptions
A7: 3 | B7: VERS.3 | C7: 1,2 | D7: 1,2 | H7: #compileOptions
A8: 4 | B8: VERS.4 | C8: 1,3 | D8: 1,3 | H8: #_root
A9: 5 | B9: VERS.5 | C9: 1,4 | D9: 2,0 | H9: constructor | O9: () | Q9: $settings | V9: ,
A10: 6 | B10: VERS.6 | C10: 2,1 | D10: 2,1 | F10: () | Q10: $options | V10: ,
A11: 7 | B11: VERS.7 | C11: 2,2 | D11: 2,2
A12: 8 | B12: VERS.8 | C12: 2,0 | D12: 3,0
A13: 9 | B13: VERS.9 | C13: 1,2 | D13: 3,0
A14: 10 | B14: VERS.10 | C14: 2,0 | D14: 2,0
A15: 11 | B15: VERS.11 | C15: 1,3 | D15: 2,0
A16: 12 | B16: VERS.12 | C16: 2,0 | D16: 3,0
A17: 13 | B17: VERS.13 | C17: 3,0 | D17: 3,1
A18: 14 | B18: VERS.14 | C18: 3,0 | D18: 3,0
A19: 15 | B19: VERS.15 | C19: 2,0 | D19: 2,0
A20: 16 | B20: VERS.16 | C20: 3,0 | D20: 3,0
A21: 17 | B21: VERS.17 | C21: 3,1 | D21: 3,1
A22: 18 | B22: VERS.18 | C22: 3,2 | D22: 3,2
G23: 0 | H23: 1 | I23: 2 | J23: 3 | K23: 4 | L23: 5 | P23: 5 | Q23: 4 | R23: 3 | S23: 2 | T23: 1 | U23: 0

Sheet DYNAMIC.5
A1: VERS | B1: Script Ledger | C1: Static 3-column programmatic language ledger
A2: SEXTER | G2: LEXTER | Q2: DEXTER
A3: ROWID | B3: VERSID | C3: LEX | E3: DEX | G3: SER | H3: TEN | N3: SYM | O3: SER | P3: TEN | V3: SYM
A4: 0 | B4: VERS.0 | G4: class | H4: EJSPiler | O4: extends | P4: Piler
A5: 1 | B5: VERS.1 | I5: #model
A6: 2 | B6: VERS.2 | I6: #renderFileOptions
A7: 3 | B7: VERS.3 | I7: #compileOptions
A8: 4 | B8: VERS.4 | I8: #_root
A9: 5 | B9: VERS.5 | I9: constructor | N9: ()
A10: 6 | B10: VERS.6 | J10: $argument1 | N10: ,
A11: 7 | B11: VERS.7 | J11: $argument2 | N11: {}
A12: 8 | B12: VERS.8
A13: 9 | B13: VERS.9
A14: 10 | B14: VERS.10
A15: 11 | B15: VERS.11
A16: 12 | B16: VERS.12
A17: 13 | B17: VERS.13
A18: 14 | B18: VERS.14
A19: 15 | B19: VERS.15
A20: 16 | B20: VERS.16
A21: 17 | B21: VERS.17
A22: 18 | B22: VERS.18
H24: 0 | I24: 1 | J24: 2 | K24: 3 | L24: 4 | M24: 5 | P24: +0 | Q24: +1 | R24: +2 | S24: +3 | T24: +4 | U24: +5

Sheet DYNAMIC.6
A1: VERS | B1: Script Ledger | C1: Static 3-column programmatic language ledger
A2: SEXTER | G2: LEXTER | Q2: DEXTER
A3: ROWID | B3: VERSID | C3: LEX | E3: DEX | G3: SER | H3: TEN | N3: SYM | O3: SER | P3: TEN | V3: SYM
A4: 0 | B4: VERS.0 | C4: 0 | E4: 0 | G4: class | H4: EJSPiler | O4: extends | P4: Piler
A5: 1 | B5: VERS.1 | C5: 1 | E5: - | I5: #model
A6: 2 | B6: VERS.2 | C6: 1 | I6: #renderFileOptions
A7: 3 | B7: VERS.3 | C7: 1 | I7: #compileOptions
A8: 4 | B8: VERS.4 | C8: 1 | I8: #_root
A9: 5 | B9: VERS.5 | C9: 1 | E9: 2 | I9: constructor | N9: () | R9: $argument1
A10: 6 | B10: VERS.6 | C10: - | E10: 2 | N10: , | R10: $argument2 | V10: {}
A11: 7 | B11: VERS.7
A12: 8 | B12: VERS.8
A13: 9 | B13: VERS.9
A14: 10 | B14: VERS.10
A15: 11 | B15: VERS.11
A16: 12 | B16: VERS.12
A17: 13 | B17: VERS.13
A18: 14 | B18: VERS.14
A19: 15 | B19: VERS.15
A20: 16 | B20: VERS.16
A21: 17 | B21: VERS.17
A22: 18 | B22: VERS.18
H24: 0 | I24: 1 | J24: 2 | K24: 3 | L24: 4 | M24: 5 | P24: +0 | Q24: +1 | R24: +2 | S24: +3 | T24: +4 | U24: +5

Sheet DYNAMIC.7
A1: VERS | B1: Script Ledger | C1: Static 3-column programmatic language ledger
A2: SEXTER | G2: LEXTER | Q2: DEXTER
A3: ROWID | B3: VERSID | C3: LEX | E3: DEX | G3: SER | H3: TEN | N3: SYM | O3: SER | P3: TEN | V3: SYM
A4: 0 | B4: VERS.0 | C4: 0 | E4: 0 | G4: class | H4: EJSPiler | O4: extends | P4: Piler | V4: {}
A5: 1 | B5: VERS.1 | C5: 1 | E5: 1 | I5: #model
A6: 2 | B6: VERS.2 | C6: 1 | E6: 1 | I6: #renderFileOptions
A7: 3 | B7: VERS.3 | C7: 1 | E7: 1 | I7: #compileOptions
A8: 4 | B8: VERS.4 | C8: 1 | E8: 1 | I8: #_root
A9: 5 | B9: VERS.5 | C9: 1 | E9: 2 | I9: constructor | N9: ()
A10: 6 | B10: VERS.6 | C10: 2 | E10: 2 | J10: $argument1 | N10: ,
A11: 7 | B11: VERS.7 | C11: 1 | E11: 2 | J11: $argument2 | N11: {}
A12: 8 | B12: VERS.8
A13: 9 | B13: VERS.9
A14: 10 | B14: VERS.10
A15: 11 | B15: VERS.11
A16: 12 | B16: VERS.12
A17: 13 | B17: VERS.13
A18: 14 | B18: VERS.14
A19: 15 | B19: VERS.15
A20: 16 | B20: VERS.16
A21: 17 | B21: VERS.17
A22: 18 | B22: VERS.18
H24: 0 | I24: 1 | J24: 2 | K24: 3 | L24: 4 | M24: 5 | P24: +0 | Q24: +1 | R24: +2 | S24: +3 | T24: +4 | U24: +5

Sheet DYNAMIC.8
A1: VERS | B1: Script Ledger | C1: Static 3-column programmatic language ledger
A2: SEXTER | G2: LEXTER | O2: DEXTER
A3: ROWID | B3: VERSID | C3: LEX | E3: DEX | G3: SER | H3: TEN | N3: SYM | O3: SER | P3: TEN | V3: SYM
A4: 0 | B4: VERS.0 | H4: a
A5: 1 | B5: VERS.1 | I5: b
A6: 2 | B6: VERS.2 | J6: c | N6: () | P6: d
A7: 3 | B7: VERS.3 | Q7: e
A8: 4 | B8: VERS.4
A9: 5 | B9: VERS.5 | J9: f
A10: 6 | B10: VERS.6 | K10: g | P10: h
A11: 7 | B11: VERS.7 | Q11: I
A12: 8 | B12: VERS.8 | R12: j
A13: 9 | B13: VERS.9 | Q13: k
A14: 10 | B14: VERS.10 | K14: l
A15: 11 | B15: VERS.11 | L15: m | P15: n
A16: 12 | B16: VERS.12 | Q16: o
A17: 13 | B17: VERS.13 | R17: p
A18: 14 | B18: VERS.14 | S18: q
A19: 15 | B19: VERS.15 | L19: r
A20: 16 | B20: VERS.16 | K20: s
A21: 17 | B21: VERS.17 | K21: t
A22: 18 | B22: VERS.18 | J22: u
A23: 19 | B23: VERS.19 | I23: v
A24: 20 | B24: VERS.20 | H24: w
A25: 21 | B25: VERS.21 | H25: x | P25: y
A26: 22 | B26: VERS.22 | Q26: z
A27: 23 | B27: VERS.23
A28: 24 | B28: VERS.24
A29: 25 | B29: VERS.25
A30: 26 | B30: VERS.26
A31: 27 | B31: VERS.27
A32: 28 | B32: VERS.28
A33: 29 | B33: VERS.29
A34: 30 | B34: VERS.30
A35: 31 | B35: VERS.31
A36: 32 | B36: VERS.32
A37: 33 | B37: VERS.33
A38: 34 | B38: VERS.34
... A46: 42 | B46: VERS.42
H47: 0 | I47: 1 | J47: 2 | K47: 3 | L47: 4 | M47: 5 | P47: +0 | Q47: +1 | R47: +2 | S47: +3 | T47: +4 | U47: +5

Sheet DYNAMIC.9
A1: VERS | B1: Script Ledger | C1: Static 3-column programmatic language ledger
A2: SEXTER | G2: LEXTER | O2: DEXTER
A3: ROWID | B3: VERSID | C3: LEX | E3: DEX | G3: SER | H3: TEN | N3: SYM | O3: SER | P3: TEN | V3: SYM
A4: 0 | B4: VERS.0 | C4: 0 | D4: 0 | E4: 0 | F4: 0 | G4: class | H4: Processes | O4: extends | P4: Core | V4: {}
A5: 1 | B5: VERS.1 | C5: 1 | D5: 0 | E5: 1 | F5: 0 | I5: length | N5: = | P5: 0
A6: 2 | B6: VERS.2 | C6: 1 | D6: 1 | E6: 1 | F6: 1 | I6: #parent
A7: 3 | B7: VERS.3 | C7: 1 | D7: 2 | E7: 1 | F7: 2 | I7: #source
A8: 4 | B8: VERS.4 | C8: 1 | D8: 3 | E8: 1 | F8: 3 | I8: #target
A9: 5 | B9: VERS.5 | C9: 1 | D9: 4 | E9: 1 | F9: 4 | I9: #_watchPaths
A10: 6 | B10: VERS.6 | C10: 1 | D10: 5 | E10: 1 | F10: 5 | I10: #watcher
A11: 7 | B11: VERS.7 | C11: 1 | D11: 6 | E11: 2 | F11: 0 | I11: constructor | N11: () | P11: $settings | V11: ,
A12: 8 | B12: VERS.8 | C12: 2 | D12: 1 | E12: 2 | F12: 1 | P12: $options | V12: ,
A13: 9 | B13: VERS.9 | C13: 2 | D13: 2 | E13: 2 | F13: 2 | P13: $parent
A14: 10 | B14: VERS.10
A15: 11 | B15: VERS.11
A16: 12 | B16: VERS.12
A17: 13 | B17: VERS.13
A18: 14 | B18: VERS.14
A19: 15 | B19: VERS.15
A20: 16 | B20: VERS.16
A21: 17 | B21: VERS.17
A22: 18 | B22: VERS.18
A23: 19 | B23: VERS.19
A24: 20 | B24: VERS.20
A25: 21 | B25: VERS.21
... A44: 40 | B44: VERS.40
A45: – | B45: – | C45: – | D45: – | E45: – | F45: – | G45: – | H45: 0 | I45: 1 | J45: 2 | K45: 3 | L45: 4 | M45: 5 | N45: – | O45: – | P45: +0 | Q45: +1 | R45: +2 | S45: +3 | T45: +4 | U45: +5 | V45: –

Sheet DYNAMIC.10
A1: VERS | B1: Script Ledger | C1: Static 3-column programmatic language ledger
A2: SEXTER | D2: LEXTER | N2: DEXTER
A3: ROWID | B3: VERSID | C3: NEX | D3: SCO | E3: BLO | F3: SER | G3: TEN | M3: SYM | N3: SER | O3: TEN | U3: SYM | V3: SCO | W3: BLO
A4: 0 | B4: VERS.0 | C4: =_xlfn.CONCAT(D4,".",E4,",",V4,".",W4) -> 0.0,0.0 | D4: 0 | E4: 0 | F4: class | G4: Processes | N4: extends | O4: Core | U4: {} | V4: 0 | W4: 0
A5: 1 | B5: VERS.1 | C5: =_xlfn.CONCAT(D5,".",E5,",",V5,".",W5) -> 1.0,1.0 | D5: 1 | E5: 0 | H5: length | M5: = | O5: 0 | V5: 1 | W5: 0
A6: 2 | B6: VERS.2 | C6: =_xlfn.CONCAT(D6,".",E6,",",V6,".",W6) -> 1.1,1.1 | D6: 1 | E6: 1 | H6: #parent | V6: 1 | W6: 1
A7: 3 | B7: VERS.3 | C7: =_xlfn.CONCAT(D7,".",E7,",",V7,".",W7) -> 1.2,1.2 | D7: 1 | E7: 2 | H7: #source | V7: 1 | W7: 2
A8: 4 | B8: VERS.4 | C8: =_xlfn.CONCAT(D8,".",E8,",",V8,".",W8) -> 1.3,1.3 | D8: 1 | E8: 3 | H8: #target | V8: 1 | W8: 3
A9: 5 | B9: VERS.5 | C9: =_xlfn.CONCAT(D9,".",E9,",",V9,".",W9) -> 1.4,1.4 | D9: 1 | E9: 4 | H9: #_watchPaths | V9: 1 | W9: 4
A10: 6 | B10: VERS.6 | C10: =_xlfn.CONCAT(D10,".",E10,",",V10,".",W10) -> 1.5,1.5 | D10: 1 | E10: 5 | H10: #watcher | V10: 1 | W10: 5
A11: 7 | B11: VERS.7 | C11: =_xlfn.CONCAT(D11,".",E11,",",V11,".",W11) -> 1.6,2.0 | D11: 1 | E11: 6 | H11: constructor | M11: () | U11: , | V11: 2 | W11: 0
A12: 8 | B12: VERS.8 | C12: =_xlfn.CONCAT(D12,".",E12,",",V12,".",W12) -> 2.1,2.1 | D12: 2 | E12: 1 | I12: $settings | M12: , | U12: , | V12: 2 | W12: 1
A13: 9 | B13: VERS.9 | C13: =_xlfn.CONCAT(D13,".",E13,",",V13,".",W13) -> 2.2,2.2 | D13: 2 | E13: 2 | I13: $options | M13: , | V13: 2 | W13: 2
A14: 10 | B14: VERS.10 | C14: =_xlfn.CONCAT(D14,".",E14,",",V14,".",W14) -> 2.3,2.3 | D14: 2 | E14: 3 | I14: $parent | V14: 2 | W14: 3
A15: 11 | B15: VERS.11 | C15: =_xlfn.CONCAT(D15,".",E15,",",V15,".",W15) -> .,.
A16: 12 | B16: VERS.12 | C16: =_xlfn.CONCAT(D16,".",E16,",",V16,".",W16) -> .,.
A17: 13 | B17: VERS.13 | C17: =_xlfn.CONCAT(D17,".",E17,",",V17,".",W17) -> .,.
A18: 14 | B18: VERS.14 | C18: =_xlfn.CONCAT(D18,".",E18,",",V18,".",W18) -> .,.
A19: 15 | B19: VERS.15 | C19: =_xlfn.CONCAT(D19,".",E19,",",V19,".",W19) -> .,.
A20: 16 | B20: VERS.16 | C20: =_xlfn.CONCAT(D20,".",E20,",",V20,".",W20) -> .,.
A21: 17 | B21: VERS.17 | C21: =_xlfn.CONCAT(D21,".",E21,",",V21,".",W21) -> .,.
A22: 18 | B22: VERS.18 | C22: =_xlfn.CONCAT(D22,".",E22,",",V22,".",W22) -> .,.
A23: 19 | B23: VERS.19 | C23: =_xlfn.CONCAT(D23,".",E23,",",V23,".",W23) -> .,.
A24: 20 | B24: VERS.20 | C24: =_xlfn.CONCAT(D24,".",E24,",",V24,".",W24) -> .,.
A25: 21 | B25: VERS.21 | C25: =_xlfn.CONCAT(D25,".",E25,",",V25,".",W25) -> .,.
A26: 22 | B26: VERS.22 | C26: =_xlfn.CONCAT(D26,".",E26,",",V26,".",W26) -> .,.
... A44: 40 | B44: VERS.40 | C44: =_xlfn.CONCAT(D44,".",E44,",",V44,".",W44) -> .,.
A45: – | B45: – | C45: – | D45: – | E45: – | F45: – | G45: 0 | H45: 1 | I45: 2 | J45: 3 | K45: 4 | L45: 5 | M45: – | N45: – | O45: +0 | P45: +1 | Q45: +2 | R45: +3 | S45: +4 | T45: +5 | U45: – | V45: – | W45: –

Sheet DYNAMIC.11
A1: VERS | B1: Script Ledger | C1: Static 3-column programmatic language ledger
A2: SEXTER | D2: LEXTER | N2: DEXTER
A3: ROWID | B3: VERSID | C3: NEXTER | D3: SCO | E3: BLO | F3: SYM | G3: SER | H3: TEN | N3: SYM | O3: SER | P3: TEN | V3: SCO | W3: BLO
A4: 0 | B4: VERS.0 | C4: =_xlfn.CONCAT(D4,".",E4,",",V4,".",W4) -> 0.0,0.0 | D4: 0 | E4: 0 | G4: class | H4: Processes | O4: extends | P4: Core | V4: 0 | W4: 0
A5: 1 | B5: VERS.1 | C5: =_xlfn.CONCAT(D5,".",E5,",",V5,".",W5) -> 1.0,1.1 | D5: 1 | E5: 0 | F5: {} | I5: length | N5: = | P5: 0 | V5: 1 | W5: 1
A6: 2 | B6: VERS.2 | C6: =_xlfn.CONCAT(D6,".",E6,",",V6,".",W6) -> 1.,1. | D6: 1 | I6: #parent | V6: 1
A7: 3 | B7: VERS.3 | C7: =_xlfn.CONCAT(D7,".",E7,",",V7,".",W7) -> 1.,1. | D7: 1 | I7: #source | V7: 1
A8: 4 | B8: VERS.4 | C8: =_xlfn.CONCAT(D8,".",E8,",",V8,".",W8) -> 1.,1. | D8: 1 | I8: #target | V8: 1
A9: 5 | B9: VERS.5 | C9: =_xlfn.CONCAT(D9,".",E9,",",V9,".",W9) -> 1.,1. | D9: 1 | I9: #_watchPaths | V9: 1
A10: 6 | B10: VERS.6 | C10: =_xlfn.CONCAT(D10,".",E10,",",V10,".",W10) -> 1.,1. | D10: 1 | I10: #watcher | V10: 1
A11: 7 | B11: VERS.7 | C11: =_xlfn.CONCAT(D11,".",E11,",",V11,".",W11) -> 1.,2.0 | D11: 1 | I11: constructor | N11: () | V11: 2 | W11: 0
A12: 8 | B12: VERS.8 | C12: =_xlfn.CONCAT(D12,".",E12,",",V12,".",W12) -> 2.1,2.1 | D12: 2 | E12: 1 | F12: , | J12: $settings | N12: , | V12: 2 | W12: 1
A13: 9 | B13: VERS.9 | C13: =_xlfn.CONCAT(D13,".",E13,",",V13,".",W13) -> 2.2,2.2 | D13: 2 | E13: 2 | F13: , | J13: $options | N13: , | V13: 2 | W13: 2
A14: 10 | B14: VERS.10 | C14: =_xlfn.CONCAT(D14,".",E14,",",V14,".",W14) -> 2.3,2.3 | D14: 2 | E14: 3 | J14: $parent | V14: 2 | W14: 3
A15: 11 | B15: VERS.11 | C15: =_xlfn.CONCAT(D15,".",E15,",",V15,".",W15) -> 2.0,. | D15: 2 | E15: 0 | F15: {}
A16: 12 | B16: VERS.12 | C16: =_xlfn.CONCAT(D16,".",E16,",",V16,".",W16) -> .,.
A17: 13 | B17: VERS.13 | C17: =_xlfn.CONCAT(D17,".",E17,",",V17,".",W17) -> .,.
A18: 14 | B18: VERS.14 | C18: =_xlfn.CONCAT(D18,".",E18,",",V18,".",W18) -> .,.
A19: 15 | B19: VERS.15 | C19: =_xlfn.CONCAT(D19,".",E19,",",V19,".",W19) -> .,.
A20: 16 | B20: VERS.16 | C20: =_xlfn.CONCAT(D20,".",E20,",",V20,".",W20) -> .,.
A21: 17 | B21: VERS.17 | C21: =_xlfn.CONCAT(D21,".",E21,",",V21,".",W21) -> .,.
A22: 18 | B22: VERS.18 | C22: =_xlfn.CONCAT(D22,".",E22,",",V22,".",W22) -> .,.
A23: 19 | B23: VERS.19 | C23: =_xlfn.CONCAT(D23,".",E23,",",V23,".",W23) -> .,.
A24: 20 | B24: VERS.20 | C24: =_xlfn.CONCAT(D24,".",E24,",",V24,".",W24) -> .,.
A25: 21 | B25: VERS.21 | C25: =_xlfn.CONCAT(D25,".",E25,",",V25,".",W25) -> .,.
A26: 22 | B26: VERS.22 | C26: =_xlfn.CONCAT(D26,".",E26,",",V26,".",W26) -> .,.
A27: 23 | B27: VERS.23 | C27: =_xlfn.CONCAT(D27,".",E27,",",V27,".",W27) -> .,.
... A44: 40 | B44: VERS.40 | C44: =_xlfn.CONCAT(D44,".",E44,",",V44,".",W44) -> .,.
A45: – | B45: – | C45: – | D45: – | E45: – | F45: – | G45: – | H45: 0 | I45: 1 | J45: 2 | K45: 3 | L45: 4 | M45: 5 | N45: – | O45: – | P45: +0 | Q45: +1 | R45: +2 | S45: +3 | T45: +4 | U45: +5 | V45: – | W45: –

Sheet DYNAMIC.12
A1: VERS | B1: Script Ledger | C1: Static 3-column programmatic language ledger
A2: SEXTER | D2: LEXTER | O2: DEXTER
A3: ROWID | B3: VERSID | C3: NEXTER | D3: SCO | E3: BLO | F3: CLO | G3: SER | H3: TEN | N3: SYM | O3: CLO | P3: SER | Q3: TEN | W3: SYM | X3: SCO | Y3: BLO
A4: 0 | B4: VERS.0 | C4: =_xlfn.CONCAT(D4,".",E4,",",X4,".",Y4) -> 0.0,0.0 | D4: 0 | E4: 0 | G4: class | H4: Processes | P4: extends | Q4: Core | X4: 0 | Y4: 0
A5: 1 | B5: VERS.1 | C5: =_xlfn.CONCAT(D5,".",E5,",",X5,".",Y5) -> 1.0,1.1 | D5: 1 | E5: 0 | F5: {} | I5: length | O5: = | Q5: 0 | X5: 1 | Y5: 1
A6: 2 | B6: VERS.2 | C6: =_xlfn.CONCAT(D6,".",E6,",",X6,".",Y6) -> 1.,1. | D6: 1 | I6: #parent | X6: 1
A7: 3 | B7: VERS.3 | C7: =_xlfn.CONCAT(D7,".",E7,",",X7,".",Y7) -> 1.,1. | D7: 1 | I7: #source | X7: 1
A8: 4 | B8: VERS.4 | C8: =_xlfn.CONCAT(D8,".",E8,",",X8,".",Y8) -> 1.,1. | D8: 1 | I8: #target | X8: 1
A9: 5 | B9: VERS.5 | C9: =_xlfn.CONCAT(D9,".",E9,",",X9,".",Y9) -> 1.,1. | D9: 1 | I9: #_watchPaths | X9: 1
A10: 6 | B10: VERS.6 | C10: =_xlfn.CONCAT(D10,".",E10,",",X10,".",Y10) -> 1.,1. | D10: 1 | I10: #watcher | X10: 1
A11: 7 | B11: VERS.7 | C11: =_xlfn.CONCAT(D11,".",E11,",",X11,".",Y11) -> 1.,2.0 | D11: 1 | I11: constructor | O11: () | X11: 2 | Y11: 0
A12: 8 | B12: VERS.8 | C12: =_xlfn.CONCAT(D12,".",E12,",",X12,".",Y12) -> 2.1,2.1 | D12: 2 | E12: 1 | F12: , | J12: $settings | O12: , | X12: 2 | Y12: 1
A13: 9 | B13: VERS.9 | C13: =_xlfn.CONCAT(D13,".",E13,",",X13,".",Y13) -> 2.2,2.2 | D13: 2 | E13: 2 | F13: , | J13: $options | O13: , | X13: 2 | Y13: 2
A14: 10 | B14: VERS.10 | C14: =_xlfn.CONCAT(D14,".",E14,",",X14,".",Y14) -> 2.3,2.3 | D14: 2 | E14: 3 | J14: $parent | X14: 2 | Y14: 3
A15: 11 | B15: VERS.11 | C15: =_xlfn.CONCAT(D15,".",E15,",",X15,".",Y15) -> 2.0,. | D15: 2 | E15: 0 | F15: {}
A16: 12 | B16: VERS.12 | C16: =_xlfn.CONCAT(D16,".",E16,",",X16,".",Y16) -> .,.
A17: 13 | B17: VERS.13 | C17: =_xlfn.CONCAT(D17,".",E17,",",X17,".",Y17) -> .,.
A18: 14 | B18: VERS.14 | C18: =_xlfn.CONCAT(D18,".",E18,",",X18,".",Y18) -> .,.
A19: 15 | B19: VERS.15 | C19: =_xlfn.CONCAT(D19,".",E19,",",X19,".",Y19) -> .,.
A20: 16 | B20: VERS.16 | C20: =_xlfn.CONCAT(D20,".",E20,",",X20,".",Y20) -> .,.
A21: 17 | B21: VERS.17 | C21: =_xlfn.CONCAT(D21,".",E21,",",X21,".",Y21) -> .,.
A22: 18 | B22: VERS.18 | C22: =_xlfn.CONCAT(D22,".",E22,",",X22,".",Y22) -> .,.
A23: 19 | B23: VERS.19 | C23: =_xlfn.CONCAT(D23,".",E23,",",X23,".",Y23) -> .,.
A24: 20 | B24: VERS.20 | C24: =_xlfn.CONCAT(D24,".",E24,",",X24,".",Y24) -> .,.
A25: 21 | B25: VERS.21 | C25: =_xlfn.CONCAT(D25,".",E25,",",X25,".",Y25) -> .,.
A26: 22 | B26: VERS.22 | C26: =_xlfn.CONCAT(D26,".",E26,",",X26,".",Y26) -> .,.
A27: 23 | B27: VERS.23 | C27: =_xlfn.CONCAT(D27,".",E27,",",X27,".",Y27) -> .,.
... A44: 40 | B44: VERS.40 | C44: =_xlfn.CONCAT(D44,".",E44,",",X44,".",Y44) -> .,.
A45: – | B45: – | C45: – | D45: – | E45: – | F45: – | G45: – | H45: 0 | I45: 1 | J45: 2 | K45: 3 | L45: 4 | M45: 5 | N45: – | O45: – | P45: – | Q45: +0 | R45: +1 | S45: +2 | T45: +3 | U45: +4 | V45: +5 | W45: – | X45: – | Y45: –

Sheet DYNAMIC.12_2
A1: VERS | B1: Script Ledger | C1: Static 3-column programmatic language ledger
A2: SEXTER | D2: LEXTER | O2: DEXTER
A3: ROWID | B3: VERSID | C3: NEXTER | D3: SCO | E3: BLO | F3: CLO | G3: SER | H3: TEN | N3: SYM | O3: CLO | P3: SER | Q3: TEN | W3: SYM | X3: SCO | Y3: BLO
A4: 0 | B4: VERS.0 | C4: =_xlfn.CONCAT(D4,".",E4,",",X4,".",Y4) -> 0.0,0.0 | D4: 0 | E4: 0 | G4: class | H4: Processes | P4: extends | X4: 0 | Y4: 0
A5: 1 | B5: VERS.1 | C5: =_xlfn.CONCAT(D5,".",E5,",",X5,".",Y5) -> 0.0,1.0 | D5: 0 | E5: 0 | F5: {} | I5: length | N5: = | Q5: 0 | X5: 1 | Y5: 0
A6: 2 | B6: VERS.2 | C6: =_xlfn.CONCAT(D6,".",E6,",",X6,".",Y6) -> 1.1,. | D6: 1 | E6: 1
A7: 3 | B7: VERS.3 | C7: =_xlfn.CONCAT(D7,".",E7,",",X7,".",Y7) -> .,.
A8: 4 | B8: VERS.4 | C8: =_xlfn.CONCAT(D8,".",E8,",",X8,".",Y8) -> .,.
A9: 5 | B9: VERS.5 | C9: =_xlfn.CONCAT(D9,".",E9,",",X9,".",Y9) -> .,.
A10: 6 | B10: VERS.6 | C10: =_xlfn.CONCAT(D10,".",E10,",",X10,".",Y10) -> .,.
A11: 7 | B11: VERS.7 | C11: =_xlfn.CONCAT(D11,".",E11,",",X11,".",Y11) -> .,.
A12: 8 | B12: VERS.8 | C12: =_xlfn.CONCAT(D12,".",E12,",",X12,".",Y12) -> .,.
A13: 9 | B13: VERS.9 | C13: =_xlfn.CONCAT(D13,".",E13,",",X13,".",Y13) -> .,.
A14: 10 | B14: VERS.10 | C14: =_xlfn.CONCAT(D14,".",E14,",",X14,".",Y14) -> .,.
A15: 11 | B15: VERS.11 | C15: =_xlfn.CONCAT(D15,".",E15,",",X15,".",Y15) -> .,.
A16: 12 | B16: VERS.12 | C16: =_xlfn.CONCAT(D16,".",E16,",",X16,".",Y16) -> .,.
A17: 13 | B17: VERS.13 | C17: =_xlfn.CONCAT(D17,".",E17,",",X17,".",Y17) -> .,.
A18: 14 | B18: VERS.14 | C18: =_xlfn.CONCAT(D18,".",E18,",",X18,".",Y18) -> .,.
... A44: 40 | B44: VERS.40 | C44: =_xlfn.CONCAT(D44,".",E44,",",X44,".",Y44) -> .,.
A45: – | B45: – | C45: – | D45: – | E45: – | F45: – | G45: – | H45: 0 | I45: 1 | J45: 2 | K45: 3 | L45: 4 | M45: 5 | N45: – | O45: – | P45: – | Q45: +0 | R45: +1 | S45: +2 | T45: +3 | U45: +4 | V45: +5 | W45: – | X45: – | Y45: –

Sheet DYNAMIC.12_2_2
A1: VERS | B1: Script Ledger | C1: Static 3-column programmatic language ledger
A2: SEXTER | D2: LEXTER | O2: DEXTER
A3: ROWID | B3: VERSID | C3: NEXTER | D3: SCO | E3: BLO | F3: SER | G3: TEN | M3: SYM | N3: CLO | O3: SER | P3: TEN | V3: SYM | W3: CLO | X3: SCO | Y3: BLO
A4: 0 | B4: VERS.0 | C4: =_xlfn.CONCAT(D4,".",E4,",",X4,".",Y4) -> 0.0,0.0 | D4: 0 | E4: 0 | F4: class | G4: Processes | O4: extends | P4: Core | W4: {} | X4: 0 | Y4: 0
A5: 1 | B5: VERS.1 | C5: =_xlfn.CONCAT(D5,".",E5,",",X5,".",Y5) -> 1.0,1.0 | D5: 1 | E5: 0 | H5: length | M5: = | Q5: 0 | X5: 1 | Y5: 0
A6: 2 | B6: VERS.2 | C6: =_xlfn.CONCAT(D6,".",E6,",",X6,".",Y6) -> 1.1,1.1 | D6: 1 | E6: 1 | H6: #parent | X6: 1 | Y6: 1
A7: 3 | B7: VERS.3 | C7: =_xlfn.CONCAT(D7,".",E7,",",X7,".",Y7) -> 1.2,1.2 | D7: 1 | E7: 2 | H7: #source | X7: 1 | Y7: 2
A8: 4 | B8: VERS.4 | C8: =_xlfn.CONCAT(D8,".",E8,",",X8,".",Y8) -> 1.3,1.3 | D8: 1 | E8: 3 | H8: #target | X8: 1 | Y8: 3
A9: 5 | B9: VERS.5 | C9: =_xlfn.CONCAT(D9,".",E9,",",X9,".",Y9) -> 1.4,1.4 | D9: 1 | E9: 4 | H9: #_watchPaths | X9: 1 | Y9: 4
A10: 6 | B10: VERS.6 | C10: =_xlfn.CONCAT(D10,".",E10,",",X10,".",Y10) -> 1.5,1.5 | D10: 1 | E10: 5 | H10: #watcher | X10: 1 | Y10: 5
A11: 7 | B11: VERS.7 | C11: =_xlfn.CONCAT(D11,".",E11,",",X11,".",Y11) -> 1.6,2.0 | D11: 1 | E11: 6 | H11: constructor | N11: () | X11: 2 | Y11: 0
A12: 8 | B12: VERS.8 | C12: =_xlfn.CONCAT(D12,".",E12,",",X12,".",Y12) -> 2.1,2.1 | D12: 2 | E12: 1 | I12: $settings | M12: , | X12: 2 | Y12: 1
A13: 9 | B13: VERS.9 | C13: =_xlfn.CONCAT(D13,".",E13,",",X13,".",Y13) -> 2.2,2.2 | D13: 2 | E13: 2 | I13: $options | M13: , | X13: 2 | Y13: 2
A14: 10 | B14: VERS.10 | C14: =_xlfn.CONCAT(D14,".",E14,",",X14,".",Y14) -> 2.3,2.3 | D14: 2 | E14: 3 | I14: $parent | X14: 2 | Y14: 3
A15: 11 | B15: VERS.11 | C15: =_xlfn.CONCAT(D15,".",E15,",",X15,".",Y15) -> .,.
A16: 12 | B16: VERS.12 | C16: =_xlfn.CONCAT(D16,".",E16,",",X16,".",Y16) -> .,.
A17: 13 | B17: VERS.13 | C17: =_xlfn.CONCAT(D17,".",E17,",",X17,".",Y17) -> .,.
A18: 14 | B18: VERS.14 | C18: =_xlfn.CONCAT(D18,".",E18,",",X18,".",Y18) -> .,.
A19: 15 | B19: VERS.15 | C19: =_xlfn.CONCAT(D19,".",E19,",",X19,".",Y19) -> .,.
A20: 16 | B20: VERS.16 | C20: =_xlfn.CONCAT(D20,".",E20,",",X20,".",Y20) -> .,.
A21: 17 | B21: VERS.17 | C21: =_xlfn.CONCAT(D21,".",E21,",",X21,".",Y21) -> .,.
A22: 18 | B22: VERS.18 | C22: =_xlfn.CONCAT(D22,".",E22,",",X22,".",Y22) -> .,.
A23: 19 | B23: VERS.19 | C23: =_xlfn.CONCAT(D23,".",E23,",",X23,".",Y23) -> .,.
A24: 20 | B24: VERS.20 | C24: =_xlfn.CONCAT(D24,".",E24,",",X24,".",Y24) -> .,.
A25: 21 | B25: VERS.21 | C25: =_xlfn.CONCAT(D25,".",E25,",",X25,".",Y25) -> .,.
A26: 22 | B26: VERS.22 | C26: =_xlfn.CONCAT(D26,".",E26,",",X26,".",Y26) -> .,.
... A44: 40 | B44: VERS.40 | C44: =_xlfn.CONCAT(D44,".",E44,",",X44,".",Y44) -> .,.
A45: – | B45: – | C45: – | D45: – | E45: – | F45: – | G45: 0 | H45: 1 | I45: 2 | J45: 3 | K45: 4 | L45: 5 | M45: – | N45: – | O45: – | P45: 0 | Q45: 1 | R45: 2 | S45: 3 | T45: 4 | U45: 5 | V45: – | W45: – | X45: – | Y45: –

Sheet DYNAMIC.100
A1: VERS
A2: FS.0 | B2: /development/processes/index.js
A3: SEXTER | C3: LEXTER | N3: DEXTER
A4: VZD | B4: NEXTER | C4: SCOPID | D4: BLOKID | E4: SER | F4: TEN | L4: SYM | M4: CLO | N4: SER | O4: TEN | U4: SYM | V4: CLO | W4: SCOPID | X4: BLOKID
A5: ='$STRUCT'!$A3 -> 0 | B5: =_xlfn.CONCAT("[",$C5,",",$D5,"]","[",$W5,",",$X5,,"]") -> [0,0][0,0] | C5: 0 | D5: 0 | E5: class | F5: Processes | N5: extends | O5: Core | V5: {} | W5: 0 | X5: 0
A6: ='$STRUCT'!$A4 -> 1 | B6: =_xlfn.CONCAT("[",$C6,",",$D6,"]","[",$W6,",",$X6,,"]") -> [1,0][1,0] | C6: 1 | D6: 0 | G6: length | L6: = | P6: 0 | W6: 1 | X6: 0
A7: ='$STRUCT'!$A5 -> 2 | B7: =_xlfn.CONCAT("[",$C7,",",$D7,"]","[",$W7,",",$X7,,"]") -> [1,1][1,1] | C7: 1 | D7: 1 | G7: #parent | W7: 1 | X7: 1
A8: ='$STRUCT'!$A6 -> 3 | B8: =_xlfn.CONCAT("[",$C8,",",$D8,"]","[",$W8,",",$X8,,"]") -> [1,2][–,–] | C8: 1 | D8: 2 | G8: #source | W8: – | X8: –
A9: ='$STRUCT'!$A7 -> 4 | B9: =_xlfn.CONCAT("[",$C9,",",$D9,"]","[",$W9,",",$X9,,"]") -> [–,–][–,–] | C9: – | D9: – | G9: #target | W9: – | X9: –
A10: ='$STRUCT'!$A8 -> 5 | B10: =_xlfn.CONCAT("[",$C10,",",$D10,"]","[",$W10,",",$X10,,"]") -> [–,–][–,–] | C10: – | D10: – | G10: #_watchPaths | W10: – | X10: –
A11: ='$STRUCT'!$A9 -> 6 | B11: =_xlfn.CONCAT("[",$C11,",",$D11,"]","[",$W11,",",$X11,,"]") -> [–,–][–,–] | C11: – | D11: – | G11: #watcher | W11: – | X11: –
A12: ='$STRUCT'!$A10 -> 7 | B12: =_xlfn.CONCAT("[",$C12,",",$D12,"]","[",$W12,",",$X12,,"]") -> [–,–][–,–] | C12: – | D12: – | G12: constructor | M12: () | W12: – | X12: –
A13: ='$STRUCT'!$A11 -> 8 | B13: =_xlfn.CONCAT("[",$C13,",",$D13,"]","[",$W13,",",$X13,,"]") -> [–,–][–,–] | C13: – | D13: – | H13: $settings | L13: , | W13: – | X13: –
A14: ='$STRUCT'!$A12 -> 9 | B14: =_xlfn.CONCAT("[",$C14,",",$D14,"]","[",$W14,",",$X14,,"]") -> [–,–][–,–] | C14: – | D14: – | H14: $options | L14: , | W14: – | X14: –
A15: ='$STRUCT'!$A13 -> 10 | B15: =_xlfn.CONCAT("[",$C15,",",$D15,"]","[",$W15,",",$X15,,"]") -> [–,–][–,–] | C15: – | D15: – | H15: $parent | W15: – | X15: –
A16: ='$STRUCT'!$A14 -> 11 | B16: =_xlfn.CONCAT("[",$C16,",",$D16,"]","[",$W16,",",$X16,,"]") -> [–,–][–,–] | C16: – | D16: – | W16: – | X16: –
A17: ='$STRUCT'!$A15 -> 12 | B17: =_xlfn.CONCAT("[",$C17,",",$D17,"]","[",$W17,",",$X17,,"]") -> [–,–][–,–] | C17: – | D17: – | W17: – | X17: –
A18: ='$STRUCT'!$A16 -> 13 | B18: =_xlfn.CONCAT("[",$C18,",",$D18,"]","[",$W18,",",$X18,,"]") -> [–,–][–,–] | C18: – | D18: – | W18: – | X18: –
A19: ='$STRUCT'!$A17 -> 14 | B19: =_xlfn.CONCAT("[",$C19,",",$D19,"]","[",$W19,",",$X19,,"]") -> [–,–][–,–] | C19: – | D19: – | W19: – | X19: –
A20: ='$STRUCT'!$A18 -> 15 | B20: =_xlfn.CONCAT("[",$C20,",",$D20,"]","[",$W20,",",$X20,,"]") -> [–,–][–,–] | C20: – | D20: – | W20: – | X20: –
A21: ='$STRUCT'!$A19 -> 16 | B21: =_xlfn.CONCAT("[",$C21,",",$D21,"]","[",$W21,",",$X21,,"]") -> [–,–][–,–] | C21: – | D21: – | W21: – | X21: –
A22: ='$STRUCT'!$A20 -> 17 | B22: =_xlfn.CONCAT("[",$C22,",",$D22,"]","[",$W22,",",$X22,,"]") -> [–,–][–,–] | C22: – | D22: – | W22: – | X22: –
A23: ='$STRUCT'!$A21 -> 18 | B23: =_xlfn.CONCAT("[",$C23,",",$D23,"]","[",$W23,",",$X23,,"]") -> [–,–][–,–] | C23: – | D23: – | W23: – | X23: –
A24: ='$STRUCT'!$A22 -> 19 | B24: =_xlfn.CONCAT("[",$C24,",",$D24,"]","[",$W24,",",$X24,,"]") -> [–,–][–,–] | C24: – | D24: – | W24: – | X24: –
A25: ='$STRUCT'!$A23 -> 20 | B25: =_xlfn.CONCAT("[",$C25,",",$D25,"]","[",$W25,",",$X25,,"]") -> [–,–][–,–] | C25: – | D25: – | W25: – | X25: –
A26: ='$STRUCT'!$A24 -> 21 | B26: =_xlfn.CONCAT("[",$C26,",",$D26,"]","[",$W26,",",$X26,,"]") -> [–,–][–,–] | C26: – | D26: – | W26: – | X26: –
A27: ='$STRUCT'!$A25 -> 22 | B27: =_xlfn.CONCAT("[",$C27,",",$D27,"]","[",$W27,",",$X27,,"]") -> [–,–][–,–] | C27: – | D27: – | W27: – | X27: –
... A45: ='$STRUCT'!$A43 -> 40 | B45: =_xlfn.CONCAT("[",$C45,",",$D45,"]","[",$W45,",",$X45,,"]") -> [–,–][–,–] | C45: – | D45: – | W45: – | X45: –
A46: HZD | B46: – | C46: – | D46: – | E46: – | F46: 0 | G46: 1 | H46: 2 | I46: 3 | J46: 4 | K46: 5 | L46: – | M46: – | N46: – | O46: 0 | P46: 1 | Q46: 2 | R46: 3 | S46: 4 | T46: 5 | U46: – | V46: – | W46: – | X46: –

Sheet DYNAMIC.101
A1: VERS
A2: FS.0 | B2: /development/processes/index.js
A3: SEXTER | C3: LEXTER | N3: DEXTER
A4: VERSID | B4: NEXTER | C4: SCOPID | D4: BLOKID | E4: SER | F4: TEN | L4: SYM | M4: CLO | N4: SER | O4: TEN | U4: SYM | V4: CLO | W4: SCOPID | X4: BLOKID
A5: =_xlfn.CONCAT($A$2, ".", '$STRUCT'!$A3) -> FS.0.0 | B5: =_xlfn.CONCAT("[",$C5,",",$D5,"]","[",$W5,",",$X5,,"]") -> [0,0][0,0] | C5: 0 | D5: 0 | E5: class | F5: Processes | N5: extends | O5: Core | V5: {} | W5: 0 | X5: 0
A6: =_xlfn.CONCAT($A$2, ".", '$STRUCT'!$A4) -> FS.0.1 | B6: =_xlfn.CONCAT("[",$C6,",",$D6,"]","[",$W6,",",$X6,,"]") -> [1,0][1,0] | C6: 1 | D6: 0 | G6: length | L6: = | P6: 0 | W6: 1 | X6: 0
A7: =_xlfn.CONCAT($A$2, ".", '$STRUCT'!$A5) -> FS.0.2 | B7: =_xlfn.CONCAT("[",$C7,",",$D7,"]","[",$W7,",",$X7,,"]") -> [1,1][1,1] | C7: 1 | D7: 1 | G7: #parent | W7: 1 | X7: 1
A8: =_xlfn.CONCAT($A$2, ".", '$STRUCT'!$A6) -> FS.0.3 | B8: =_xlfn.CONCAT("[",$C8,",",$D8,"]","[",$W8,",",$X8,,"]") -> [1,2][1,2] | C8: 1 | D8: 2 | G8: #source | W8: 1 | X8: 2
A9: =_xlfn.CONCAT($A$2, ".", '$STRUCT'!$A7) -> FS.0.4 | B9: =_xlfn.CONCAT("[",$C9,",",$D9,"]","[",$W9,",",$X9,,"]") -> [1,3][1,3] | C9: 1 | D9: 3 | G9: #target | W9: 1 | X9: 3
A10: =_xlfn.CONCAT($A$2, ".", '$STRUCT'!$A8) -> FS.0.5 | B10: =_xlfn.CONCAT("[",$C10,",",$D10,"]","[",$W10,",",$X10,,"]") -> [1,4][1,4] | C10: 1 | D10: 4 | G10: #_watchPaths | W10: 1 | X10: 4
A11: =_xlfn.CONCAT($A$2, ".", '$STRUCT'!$A9) -> FS.0.6 | B11: =_xlfn.CONCAT("[",$C11,",",$D11,"]","[",$W11,",",$X11,,"]") -> [1,5][1,5] | C11: 1 | D11: 5 | G11: #watcher | W11: 1 | X11: 5
A12: =_xlfn.CONCAT($A$2, ".", '$STRUCT'!$A10) -> FS.0.7 | B12: =_xlfn.CONCAT("[",$C12,",",$D12,"]","[",$W12,",",$X12,,"]") -> [1,6][2,0] | C12: 1 | D12: 6 | G12: constructor | M12: () | W12: 2 | X12: 0
A13: =_xlfn.CONCAT($A$2, ".", '$STRUCT'!$A11) -> FS.0.8 | B13: =_xlfn.CONCAT("[",$C13,",",$D13,"]","[",$W13,",",$X13,,"]") -> [–,–][–,–] | C13: – | D13: – | H13: $settings | L13: , | W13: – | X13: –
A14: =_xlfn.CONCAT($A$2, ".", '$STRUCT'!$A12) -> FS.0.9 | B14: =_xlfn.CONCAT("[",$C14,",",$D14,"]","[",$W14,",",$X14,,"]") -> [–,–][–,–] | C14: – | D14: – | H14: $options | L14: , | W14: – | X14: –
A15: =_xlfn.CONCAT($A$2, ".", '$STRUCT'!$A13) -> FS.0.10 | B15: =_xlfn.CONCAT("[",$C15,",",$D15,"]","[",$W15,",",$X15,,"]") -> [–,–][–,–] | C15: – | D15: – | H15: $parent | W15: – | X15: –
A16: =_xlfn.CONCAT($A$2, ".", '$STRUCT'!$A14) -> FS.0.11 | B16: =_xlfn.CONCAT("[",$C16,",",$D16,"]","[",$W16,",",$X16,,"]") -> [–,–][–,–] | C16: – | D16: – | W16: – | X16: –
A17: =_xlfn.CONCAT($A$2, ".", '$STRUCT'!$A15) -> FS.0.12 | B17: =_xlfn.CONCAT("[",$C17,",",$D17,"]","[",$W17,",",$X17,,"]") -> [–,–][–,–] | C17: – | D17: – | W17: – | X17: –
A18: =_xlfn.CONCAT($A$2, ".", '$STRUCT'!$A16) -> FS.0.13 | B18: =_xlfn.CONCAT("[",$C18,",",$D18,"]","[",$W18,",",$X18,,"]") -> [–,–][–,–] | C18: – | D18: – | W18: – | X18: –
A19: =_xlfn.CONCAT($A$2, ".", '$STRUCT'!$A17) -> FS.0.14 | B19: =_xlfn.CONCAT("[",$C19,",",$D19,"]","[",$W19,",",$X19,,"]") -> [–,–][–,–] | C19: – | D19: – | W19: – | X19: –
A20: =_xlfn.CONCAT($A$2, ".", '$STRUCT'!$A18) -> FS.0.15 | B20: =_xlfn.CONCAT("[",$C20,",",$D20,"]","[",$W20,",",$X20,,"]") -> [–,–][–,–] | C20: – | D20: – | W20: – | X20: –
A21: =_xlfn.CONCAT($A$2, ".", '$STRUCT'!$A19) -> FS.0.16 | B21: =_xlfn.CONCAT("[",$C21,",",$D21,"]","[",$W21,",",$X21,,"]") -> [–,–][–,–] | C21: – | D21: – | W21: – | X21: –
A22: =_xlfn.CONCAT($A$2, ".", '$STRUCT'!$A20) -> FS.0.17 | B22: =_xlfn.CONCAT("[",$C22,",",$D22,"]","[",$W22,",",$X22,,"]") -> [–,–][–,–] | C22: – | D22: – | W22: – | X22: –
A23: =_xlfn.CONCAT($A$2, ".", '$STRUCT'!$A21) -> FS.0.18 | B23: =_xlfn.CONCAT("[",$C23,",",$D23,"]","[",$W23,",",$X23,,"]") -> [–,–][–,–] | C23: – | D23: – | W23: – | X23: –
A24: =_xlfn.CONCAT($A$2, ".", '$STRUCT'!$A22) -> FS.0.19 | B24: =_xlfn.CONCAT("[",$C24,",",$D24,"]","[",$W24,",",$X24,,"]") -> [–,–][–,–] | C24: – | D24: – | W24: – | X24: –
A25: =_xlfn.CONCAT($A$2, ".", '$STRUCT'!$A23) -> FS.0.20 | B25: =_xlfn.CONCAT("[",$C25,",",$D25,"]","[",$W25,",",$X25,,"]") -> [–,–][–,–] | C25: – | D25: – | W25: – | X25: –
A26: =_xlfn.CONCAT($A$2, ".", '$STRUCT'!$A24) -> FS.0.21 | B26: =_xlfn.CONCAT("[",$C26,",",$D26,"]","[",$W26,",",$X26,,"]") -> [–,–][–,–] | C26: – | D26: – | W26: – | X26: –
A27: =_xlfn.CONCAT($A$2, ".", '$STRUCT'!$A25) -> FS.0.22 | B27: =_xlfn.CONCAT("[",$C27,",",$D27,"]","[",$W27,",",$X27,,"]") -> [–,–][–,–] | C27: – | D27: – | W27: – | X27: –
... A45: =_xlfn.CONCAT($A$2, ".", '$STRUCT'!$A43) -> FS.0.40 | B45: =_xlfn.CONCAT("[",$C45,",",$D45,"]","[",$W45,",",$X45,,"]") -> [–,–][–,–] | C45: – | D45: – | W45: – | X45: –
A46: – | B46: – | C46: – | D46: – | E46: – | F46: 0 | G46: 1 | H46: 2 | I46: 3 | J46: 4 | K46: 5 | L46: – | M46: – | N46: – | O46: 0 | P46: 1 | Q46: 2 | R46: 3 | S46: 4 | T46: 5 | U46: – | V46: – | W46: – | X46: –

Sheet DYNAMIC.102
A1: VERS
A2: FS.0 | B2: /development/processes/index.js
A3: SEXTER | C3: LEXTER | N3: DEXTER
A4: VERSID | B4: NEXTER | C4: SCOPID | D4: BLOKID | E4: SER | F4: TEN | L4: SYM | M4: CLO | N4: SER | O4: TEN | U4: SYM | V4: CLO | W4: SCOPID | X4: BLOKID
A5: =_xlfn.CONCAT($A$2, ".", '$STRUCT'!$A3) -> FS.0.0 | B5: =_xlfn.CONCAT($C5,".",$D5,",",$W5,".",$X5) -> 0.0,0.0 | C5: 0 | D5: 0 | E5: class | F5: Processes | N5: extends | O5: Core | V5: {} | W5: 0 | X5: 0
A6: =_xlfn.CONCAT($A$2, ".", '$STRUCT'!$A4) -> FS.0.1 | B6: =_xlfn.CONCAT($C6,".",$D6,",",$W6,".",$X6) -> 1.0,1.0 | C6: 1 | D6: 0 | G6: length | L6: = | P6: 0 | W6: 1 | X6: 0
A7: =_xlfn.CONCAT($A$2, ".", '$STRUCT'!$A5) -> FS.0.2 | B7: =_xlfn.CONCAT($C7,".",$D7,",",$W7,".",$X7) -> 1.1,1.1 | C7: 1 | D7: 1 | G7: #parent | W7: 1 | X7: 1
A8: =_xlfn.CONCAT($A$2, ".", '$STRUCT'!$A6) -> FS.0.3 | B8: =_xlfn.CONCAT($C8,".",$D8,",",$W8,".",$X8) -> 1.2,1.2 | C8: 1 | D8: 2 | G8: #source | W8: 1 | X8: 2
A9: =_xlfn.CONCAT($A$2, ".", '$STRUCT'!$A7) -> FS.0.4 | B9: =_xlfn.CONCAT($C9,".",$D9,",",$W9,".",$X9) -> 1.3,1.3 | C9: 1 | D9: 3 | G9: #target | W9: 1 | X9: 3
A10: =_xlfn.CONCAT($A$2, ".", '$STRUCT'!$A8) -> FS.0.5 | B10: =_xlfn.CONCAT($C10,".",$D10,",",$W10,".",$X10) -> 1.4,1.4 | C10: 1 | D10: 4 | G10: #_watchPaths | W10: 1 | X10: 4
A11: =_xlfn.CONCAT($A$2, ".", '$STRUCT'!$A9) -> FS.0.6 | B11: =_xlfn.CONCAT($C11,".",$D11,",",$W11,".",$X11) -> 1.5,1.5 | C11: 1 | D11: 5 | G11: #watcher | W11: 1 | X11: 5
A12: =_xlfn.CONCAT($A$2, ".", '$STRUCT'!$A10) -> FS.0.7 | B12: =_xlfn.CONCAT($C12,".",$D12,",",$W12,".",$X12) -> 1.6,1.6 | C12: 1 | D12: 6 | G12: constructor | M12: () | W12: 1 | X12: 6
A13: =_xlfn.CONCAT($A$2, ".", '$STRUCT'!$A11) -> FS.0.8 | B13: =_xlfn.CONCAT($C13,".",$D13,",",$W13,".",$X13) -> 2.0,2.0 | C13: 2 | D13: 0 | H13: $settings | L13: , | W13: 2 | X13: 0
A14: =_xlfn.CONCAT($A$2, ".", '$STRUCT'!$A12) -> FS.0.9 | B14: =_xlfn.CONCAT($C14,".",$D14,",",$W14,".",$X14) -> 2.1,2.1 | C14: 2 | D14: 1 | H14: $options | L14: , | W14: 2 | X14: 1
A15: =_xlfn.CONCAT($A$2, ".", '$STRUCT'!$A13) -> FS.0.10 | B15: =_xlfn.CONCAT($C15,".",$D15,",",$W15,".",$X15) -> 2.2,2.2 | C15: 2 | D15: 2 | H15: $parent | W15: 2 | X15: 2
A16: =_xlfn.CONCAT($A$2, ".", '$STRUCT'!$A14) -> FS.0.11 | B16: =_xlfn.CONCAT($C16,".",$D16,",",$W16,".",$X16) -> 1.7,1.7 | C16: 1 | D16: 7 | M16: {} | W16: 1 | X16: 7
A17: =_xlfn.CONCAT($A$2, ".", '$STRUCT'!$A15) -> FS.0.12 | B17: =_xlfn.CONCAT($C17,".",$D17,",",$W17,".",$X17) -> 2.0,2.0 | C17: 2 | D17: 0 | H17: super | M17: () | W17: 2 | X17: 0
A18: =_xlfn.CONCAT($A$2, ".", '$STRUCT'!$A16) -> FS.0.13 | B18: =_xlfn.CONCAT($C18,".",$D18,",",$W18,".",$X18) -> 3.0,3.0 | C18: 3 | D18: 0 | I18: ...arguments | W18: 3 | X18: 0
A19: =_xlfn.CONCAT($A$2, ".", '$STRUCT'!$A17) -> FS.0.14 | B19: =_xlfn.CONCAT($C19,".",$D19,",",$W19,".",$X19) -> 2.1,–.– | C19: 2 | D19: 1 | H19: this.#parent | L19: = | R19: $parent | W19: – | X19: –
A20: =_xlfn.CONCAT($A$2, ".", '$STRUCT'!$A18) -> FS.0.15 | B20: =_xlfn.CONCAT($C20,".",$D20,",",$W20,".",$X20) -> –.–,–.– | C20: – | D20: – | W20: – | X20: –
A21: =_xlfn.CONCAT($A$2, ".", '$STRUCT'!$A19) -> FS.0.16 | B21: =_xlfn.CONCAT($C21,".",$D21,",",$W21,".",$X21) -> –.–,–.– | C21: – | D21: – | W21: – | X21: –
A22: =_xlfn.CONCAT($A$2, ".", '$STRUCT'!$A20) -> FS.0.17 | B22: =_xlfn.CONCAT($C22,".",$D22,",",$W22,".",$X22) -> –.–,–.– | C22: – | D22: – | W22: – | X22: –
A23: =_xlfn.CONCAT($A$2, ".", '$STRUCT'!$A21) -> FS.0.18 | B23: =_xlfn.CONCAT($C23,".",$D23,",",$W23,".",$X23) -> –.–,–.– | C23: – | D23: – | W23: – | X23: –
A24: =_xlfn.CONCAT($A$2, ".", '$STRUCT'!$A22) -> FS.0.19 | B24: =_xlfn.CONCAT($C24,".",$D24,",",$W24,".",$X24) -> –.–,–.– | C24: – | D24: – | W24: – | X24: –
A25: =_xlfn.CONCAT($A$2, ".", '$STRUCT'!$A23) -> FS.0.20 | B25: =_xlfn.CONCAT($C25,".",$D25,",",$W25,".",$X25) -> –.–,–.– | C25: – | D25: – | W25: – | X25: –
A26: =_xlfn.CONCAT($A$2, ".", '$STRUCT'!$A24) -> FS.0.21 | B26: =_xlfn.CONCAT($C26,".",$D26,",",$W26,".",$X26) -> –.–,–.– | C26: – | D26: – | W26: – | X26: –
A27: =_xlfn.CONCAT($A$2, ".", '$STRUCT'!$A25) -> FS.0.22 | B27: =_xlfn.CONCAT($C27,".",$D27,",",$W27,".",$X27) -> –.–,–.– | C27: – | D27: – | W27: – | X27: –
A28: =_xlfn.CONCAT($A$2, ".", '$STRUCT'!$A26) -> FS.0.23 | B28: =_xlfn.CONCAT($C28,".",$D28,",",$W28,".",$X28) -> –.–,–.– | C28: – | D28: – | W28: – | X28: –
A29: =_xlfn.CONCAT($A$2, ".", '$STRUCT'!$A27) -> FS.0.24 | B29: =_xlfn.CONCAT($C29,".",$D29,",",$W29,".",$X29) -> –.–,–.– | C29: – | D29: – | W29: – | X29: –
A30: =_xlfn.CONCAT($A$2, ".", '$STRUCT'!$A28) -> FS.0.25 | B30: =_xlfn.CONCAT($C30,".",$D30,",",$W30,".",$X30) -> –.–,–.– | C30: – | D30: – | W30: – | X30: –
A31: =_xlfn.CONCAT($A$2, ".", '$STRUCT'!$A29) -> FS.0.26 | B31: =_xlfn.CONCAT($C31,".",$D31,",",$W31,".",$X31) -> –.–,–.– | C31: – | D31: – | W31: – | X31: –
... A45: =_xlfn.CONCAT($A$2, ".", '$STRUCT'!$A43) -> FS.0.40 | B45: =_xlfn.CONCAT($C45,".",$D45,",",$W45,".",$X45) -> –.–,–.– | C45: – | D45: – | W45: – | X45: –
A46: – | B46: =_xlfn.CONCAT($C46,".",$D46,",",$W46,".",$X46) -> –.–,–.– | C46: – | D46: – | E46: – | F46: 0 | G46: 1 | H46: 2 | I46: 3 | J46: 4 | K46: 5 | L46: – | M46: – | N46: – | O46: 0 | P46: 1 | Q46: 2 | R46: 3 | S46: 4 | T46: 5 | U46: – | V46: – | W46: – | X46: –

Sheet DYNAMIC.103
A1: VERS
A2: FS.0 | B2: /development/processes/index.js
A3: SEXTER | C3: LEXTER | M3: DEXTER
A4: VERSID | B4: NEXTER | C4: SCOPID | D4: BLOKID | E4: SER | F4: TEN | L4: SYM | M4: SER | N4: TEN | T4: SYM | U4: SCOPID | V4: BLOKID
A5: =_xlfn.CONCAT($A$2, ".", '$STRUCT'!$A3) -> FS.0.0 | B5: =_xlfn.CONCAT($C5,".",$D5,",",$U5,".",$V5) -> 0.0,0.0 | C5: 0 | D5: 0 | E5: class | F5: Processes | M5: extends | N5: Core | T5: {} | U5: 0 | V5: 0
A6: =_xlfn.CONCAT($A$2, ".", '$STRUCT'!$A4) -> FS.0.1 | B6: =_xlfn.CONCAT($C6,".",$D6,",",$U6,".",$V6) -> 1.0,1.0 | C6: 1 | D6: 0 | G6: length | L6: = | O6: 0 | U6: 1 | V6: 0
A7: =_xlfn.CONCAT($A$2, ".", '$STRUCT'!$A5) -> FS.0.2 | B7: =_xlfn.CONCAT($C7,".",$D7,",",$U7,".",$V7) -> 1.1,1.1 | C7: 1 | D7: 1 | G7: #parent | U7: 1 | V7: 1
A8: =_xlfn.CONCAT($A$2, ".", '$STRUCT'!$A6) -> FS.0.3 | B8: =_xlfn.CONCAT($C8,".",$D8,",",$U8,".",$V8) -> 1.2,1.2 | C8: 1 | D8: 2 | G8: #source | U8: 1 | V8: 2
A9: =_xlfn.CONCAT($A$2, ".", '$STRUCT'!$A7) -> FS.0.4 | B9: =_xlfn.CONCAT($C9,".",$D9,",",$U9,".",$V9) -> 1.3,1.3 | C9: 1 | D9: 3 | G9: #target | U9: 1 | V9: 3
A10: =_xlfn.CONCAT($A$2, ".", '$STRUCT'!$A8) -> FS.0.5 | B10: =_xlfn.CONCAT($C10,".",$D10,",",$U10,".",$V10) -> 1.4,1.4 | C10: 1 | D10: 4 | G10: #_watchPaths | U10: 1 | V10: 4
A11: =_xlfn.CONCAT($A$2, ".", '$STRUCT'!$A9) -> FS.0.6 | B11: =_xlfn.CONCAT($C11,".",$D11,",",$U11,".",$V11) -> 1.5,1.5 | C11: 1 | D11: 5 | G11: #watcher | U11: 1 | V11: 5
A12: =_xlfn.CONCAT($A$2, ".", '$STRUCT'!$A10) -> FS.0.7 | B12: =_xlfn.CONCAT($C12,".",$D12,",",$U12,".",$V12) -> 1.6,1.6 | C12: 1 | D12: 6 | G12: constructor | L12: () | U12: 1 | V12: 6
A13: =_xlfn.CONCAT($A$2, ".", '$STRUCT'!$A11) -> FS.0.8 | B13: =_xlfn.CONCAT($C13,".",$D13,",",$U13,".",$V13) -> 2.0,2.0 | C13: 2 | D13: 0 | H13: $settings | L13: , | U13: 2 | V13: 0
A14: =_xlfn.CONCAT($A$2, ".", '$STRUCT'!$A12) -> FS.0.9 | B14: =_xlfn.CONCAT($C14,".",$D14,",",$U14,".",$V14) -> 2.1,2.1 | C14: 2 | D14: 1 | H14: $options | L14: , | U14: 2 | V14: 1
A15: =_xlfn.CONCAT($A$2, ".", '$STRUCT'!$A13) -> FS.0.10 | B15: =_xlfn.CONCAT($C15,".",$D15,",",$U15,".",$V15) -> 2.2,2.2 | C15: 2 | D15: 2 | H15: $parent | U15: 2 | V15: 2
A16: =_xlfn.CONCAT($A$2, ".", '$STRUCT'!$A14) -> FS.0.11 | B16: =_xlfn.CONCAT($C16,".",$D16,",",$U16,".",$V16) -> 1.7,1.7 | C16: 1 | D16: 7 | L16: {} | U16: 1 | V16: 7
A17: =_xlfn.CONCAT($A$2, ".", '$STRUCT'!$A15) -> FS.0.12 | B17: =_xlfn.CONCAT($C17,".",$D17,",",$U17,".",$V17) -> 2.0,2.0 | C17: 2 | D17: 0 | H17: super | L17: () | U17: 2 | V17: 0
A18: =_xlfn.CONCAT($A$2, ".", '$STRUCT'!$A16) -> FS.0.13 | B18: =_xlfn.CONCAT($C18,".",$D18,",",$U18,".",$V18) -> 3.0,3.0 | C18: 3 | D18: 0 | I18: ...arguments | U18: 3 | V18: 0
A19: =_xlfn.CONCAT($A$2, ".", '$STRUCT'!$A17) -> FS.0.14 | B19: =_xlfn.CONCAT($C19,".",$D19,",",$U19,".",$V19) -> 2.1,2.1 | C19: 2 | D19: 1 | H19: this.#parent | L19: = | Q19: $parent | U19: 2 | V19: 1
A20: =_xlfn.CONCAT($A$2, ".", '$STRUCT'!$A18) -> FS.0.15 | B20: =_xlfn.CONCAT($C20,".",$D20,",",$U20,".",$V20) -> 2.2,2.2 | C20: 2 | D20: 2 | H20: this.addEvents | L20: () | U20: 2 | V20: 2
A21: =_xlfn.CONCAT($A$2, ".", '$STRUCT'!$A19) -> FS.0.16 | B21: =_xlfn.CONCAT($C21,".",$D21,",",$U21,".",$V21) -> 3.0,3.0 | C21: 3 | D21: 0 | L21: [] | U21: 3 | V21: 0
A22: =_xlfn.CONCAT($A$2, ".", '$STRUCT'!$A20) -> FS.0.17 | B22: =_xlfn.CONCAT($C22,".",$D22,",",$U22,".",$V22) -> –.–,–.– | C22: – | D22: – | U22: – | V22: –
A23: =_xlfn.CONCAT($A$2, ".", '$STRUCT'!$A21) -> FS.0.18 | B23: =_xlfn.CONCAT($C23,".",$D23,",",$U23,".",$V23) -> –.–,–.– | C23: – | D23: – | U23: – | V23: –
A24: =_xlfn.CONCAT($A$2, ".", '$STRUCT'!$A22) -> FS.0.19 | B24: =_xlfn.CONCAT($C24,".",$D24,",",$U24,".",$V24) -> –.–,–.– | C24: – | D24: – | U24: – | V24: –
A25: =_xlfn.CONCAT($A$2, ".", '$STRUCT'!$A23) -> FS.0.20 | B25: =_xlfn.CONCAT($C25,".",$D25,",",$U25,".",$V25) -> –.–,–.– | C25: – | D25: – | U25: – | V25: –
A26: =_xlfn.CONCAT($A$2, ".", '$STRUCT'!$A24) -> FS.0.21 | B26: =_xlfn.CONCAT($C26,".",$D26,",",$U26,".",$V26) -> –.–,–.– | C26: – | D26: – | U26: – | V26: –
A27: =_xlfn.CONCAT($A$2, ".", '$STRUCT'!$A25) -> FS.0.22 | B27: =_xlfn.CONCAT($C27,".",$D27,",",$U27,".",$V27) -> –.–,–.– | C27: – | D27: – | U27: – | V27: –
A28: =_xlfn.CONCAT($A$2, ".", '$STRUCT'!$A26) -> FS.0.23 | B28: =_xlfn.CONCAT($C28,".",$D28,",",$U28,".",$V28) -> –.–,–.– | C28: – | D28: – | U28: – | V28: –
A29: =_xlfn.CONCAT($A$2, ".", '$STRUCT'!$A27) -> FS.0.24 | B29: =_xlfn.CONCAT($C29,".",$D29,",",$U29,".",$V29) -> –.–,–.– | C29: – | D29: – | U29: – | V29: –
A30: =_xlfn.CONCAT($A$2, ".", '$STRUCT'!$A28) -> FS.0.25 | B30: =_xlfn.CONCAT($C30,".",$D30,",",$U30,".",$V30) -> –.–,–.– | C30: – | D30: – | U30: – | V30: –
A31: =_xlfn.CONCAT($A$2, ".", '$STRUCT'!$A29) -> FS.0.26 | B31: =_xlfn.CONCAT($C31,".",$D31,",",$U31,".",$V31) -> –.–,–.– | C31: – | D31: – | U31: – | V31: –
A32: =_xlfn.CONCAT($A$2, ".", '$STRUCT'!$A30) -> FS.0.27 | B32: =_xlfn.CONCAT($C32,".",$D32,",",$U32,".",$V32) -> –.–,–.– | C32: – | D32: – | U32: – | V32: –
A33: =_xlfn.CONCAT($A$2, ".", '$STRUCT'!$A31) -> FS.0.28 | B33: =_xlfn.CONCAT($C33,".",$D33,",",$U33,".",$V33) -> –.–,–.– | C33: – | D33: – | U33: – | V33: –
... A45: =_xlfn.CONCAT($A$2, ".", '$STRUCT'!$A43) -> FS.0.40 | B45: =_xlfn.CONCAT($C45,".",$D45,",",$U45,".",$V45) -> –.–,–.– | C45: – | D45: – | U45: – | V45: –
A46: – | B46: =_xlfn.CONCAT($C46,".",$D46,",",$U46,".",$V46) -> –.–,–.– | C46: – | D46: – | E46: – | F46: 0 | G46: 1 | H46: 2 | I46: 3 | J46: 4 | K46: 5 | L46: – | M46: – | N46: 0 | O46: 1 | P46: 2 | Q46: 3 | R46: 4 | S46: 5 | T46: – | U46: – | V46: –

Sheet DYNAMIC.104
A1: VERS
A2: FS.0 | B2: /development/processes/index.js
A3: SEXTER | C3: LEXTER | M3: DEXTER
A4: VERSID | B4: NEXTER | C4: SCOPID | D4: BLOKID | E4: SER | F4: TEN | L4: SYM | M4: SER | N4: TEN | T4: SYM | U4: SCOPID | V4: BLOKID
A5: =_xlfn.CONCAT($A$2, ".", '$STRUCT'!$A3) -> FS.0.0 | B5: =_xlfn.CONCAT($C5,".",$D5,",",$U5,".",$V5) -> 0.0,0.0 | C5: 0 | D5: 0 | E5: class | F5: Processes | M5: extends | N5: Core | T5: {} | U5: 0 | V5: 0
A6: =_xlfn.CONCAT($A$2, ".", '$STRUCT'!$A4) -> FS.0.1 | B6: =_xlfn.CONCAT($C6,".",$D6,",",$U6,".",$V6) -> 1.0,1.0 | C6: 1 | D6: 0 | G6: length | L6: = | O6: 0 | U6: 1 | V6: 0
A7: =_xlfn.CONCAT($A$2, ".", '$STRUCT'!$A5) -> FS.0.2 | B7: =_xlfn.CONCAT($C7,".",$D7,",",$U7,".",$V7) -> 1.1,1.1 | C7: 1 | D7: 1 | G7: #parent | U7: 1 | V7: 1
A8: =_xlfn.CONCAT($A$2, ".", '$STRUCT'!$A6) -> FS.0.3 | B8: =_xlfn.CONCAT($C8,".",$D8,",",$U8,".",$V8) -> 1.2,1.2 | C8: 1 | D8: 2 | G8: #source | U8: 1 | V8: 2
A9: =_xlfn.CONCAT($A$2, ".", '$STRUCT'!$A7) -> FS.0.4 | B9: =_xlfn.CONCAT($C9,".",$D9,",",$U9,".",$V9) -> 1.3,1.3 | C9: 1 | D9: 3 | G9: #target | U9: 1 | V9: 3
A10: =_xlfn.CONCAT($A$2, ".", '$STRUCT'!$A8) -> FS.0.5 | B10: =_xlfn.CONCAT($C10,".",$D10,",",$U10,".",$V10) -> 1.4,1.4 | C10: 1 | D10: 4 | G10: #_watchPaths | U10: 1 | V10: 4
A11: =_xlfn.CONCAT($A$2, ".", '$STRUCT'!$A9) -> FS.0.6 | B11: =_xlfn.CONCAT($C11,".",$D11,",",$U11,".",$V11) -> 1.5,1.5 | C11: 1 | D11: 5 | G11: #watcher | U11: 1 | V11: 5
A12: =_xlfn.CONCAT($A$2, ".", '$STRUCT'!$A10) -> FS.0.7 | B12: =_xlfn.CONCAT($C12,".",$D12,",",$U12,".",$V12) -> 1.6,1.6 | C12: 1 | D12: 6 | G12: constructor | L12: () | U12: 1 | V12: 6
A13: =_xlfn.CONCAT($A$2, ".", '$STRUCT'!$A11) -> FS.0.8 | B13: =_xlfn.CONCAT($C13,".",$D13,",",$U13,".",$V13) -> 2.0,2.0 | C13: 2 | D13: 0 | H13: $settings | L13: , | U13: 2 | V13: 0
A14: =_xlfn.CONCAT($A$2, ".", '$STRUCT'!$A12) -> FS.0.9 | B14: =_xlfn.CONCAT($C14,".",$D14,",",$U14,".",$V14) -> 2.1,2.1 | C14: 2 | D14: 1 | H14: $options | L14: , | U14: 2 | V14: 1
A15: =_xlfn.CONCAT($A$2, ".", '$STRUCT'!$A13) -> FS.0.10 | B15: =_xlfn.CONCAT($C15,".",$D15,",",$U15,".",$V15) -> 2.2,2.2 | C15: 2 | D15: 2 | H15: $parent | U15: 2 | V15: 2
A16: =_xlfn.CONCAT($A$2, ".", '$STRUCT'!$A14) -> FS.0.11 | B16: =_xlfn.CONCAT($C16,".",$D16,",",$U16,".",$V16) -> 1.7,1.7 | C16: 1 | D16: 7 | L16: {} | U16: 1 | V16: 7
A17: =_xlfn.CONCAT($A$2, ".", '$STRUCT'!$A15) -> FS.0.12 | B17: =_xlfn.CONCAT($C17,".",$D17,",",$U17,".",$V17) -> 2.0,2.0 | C17: 2 | D17: 0 | H17: super | L17: () | U17: 2 | V17: 0
A18: =_xlfn.CONCAT($A$2, ".", '$STRUCT'!$A16) -> FS.0.13 | B18: =_xlfn.CONCAT($C18,".",$D18,",",$U18,".",$V18) -> 3.0,3.0 | C18: 3 | D18: 0 | I18: ...arguments | U18: 3 | V18: 0
A19: =_xlfn.CONCAT($A$2, ".", '$STRUCT'!$A17) -> FS.0.14 | B19: =_xlfn.CONCAT($C19,".",$D19,",",$U19,".",$V19) -> 2.1,2.1 | C19: 2 | D19: 1 | H19: this.#parent | L19: = | Q19: $parent | U19: 2 | V19: 1
A20: =_xlfn.CONCAT($A$2, ".", '$STRUCT'!$A18) -> FS.0.15 | B20: =_xlfn.CONCAT($C20,".",$D20,",",$U20,".",$V20) -> 2.2,2.2 | C20: 2 | D20: 2 | H20: this.addEvents | L20: ([]) | U20: 2 | V20: 2
A21: =_xlfn.CONCAT($A$2, ".", '$STRUCT'!$A19) -> FS.0.16 | B21: =_xlfn.CONCAT($C21,".",$D21,",",$U21,".",$V21) -> 4.0,4.0 | C21: 4 | D21: 0 | L21: {} | U21: 4 | V21: 0
A22: =_xlfn.CONCAT($A$2, ".", '$STRUCT'!$A20) -> FS.0.17 | B22: =_xlfn.CONCAT($C22,".",$D22,",",$U22,".",$V22) -> –.–,–.– | C22: – | D22: – | U22: – | V22: –
A23: =_xlfn.CONCAT($A$2, ".", '$STRUCT'!$A21) -> FS.0.18 | B23: =_xlfn.CONCAT($C23,".",$D23,",",$U23,".",$V23) -> –.–,–.– | C23: – | D23: – | U23: – | V23: –
A24: =_xlfn.CONCAT($A$2, ".", '$STRUCT'!$A22) -> FS.0.19 | B24: =_xlfn.CONCAT($C24,".",$D24,",",$U24,".",$V24) -> –.–,–.– | C24: – | D24: – | U24: – | V24: –
A25: =_xlfn.CONCAT($A$2, ".", '$STRUCT'!$A23) -> FS.0.20 | B25: =_xlfn.CONCAT($C25,".",$D25,",",$U25,".",$V25) -> –.–,–.– | C25: – | D25: – | U25: – | V25: –
A26: =_xlfn.CONCAT($A$2, ".", '$STRUCT'!$A24) -> FS.0.21 | B26: =_xlfn.CONCAT($C26,".",$D26,",",$U26,".",$V26) -> –.–,–.– | C26: – | D26: – | U26: – | V26: –
A27: =_xlfn.CONCAT($A$2, ".", '$STRUCT'!$A25) -> FS.0.22 | B27: =_xlfn.CONCAT($C27,".",$D27,",",$U27,".",$V27) -> –.–,–.– | C27: – | D27: – | U27: – | V27: –
A28: =_xlfn.CONCAT($A$2, ".", '$STRUCT'!$A26) -> FS.0.23 | B28: =_xlfn.CONCAT($C28,".",$D28,",",$U28,".",$V28) -> –.–,–.– | C28: – | D28: – | U28: – | V28: –
A29: =_xlfn.CONCAT($A$2, ".", '$STRUCT'!$A27) -> FS.0.24 | B29: =_xlfn.CONCAT($C29,".",$D29,",",$U29,".",$V29) -> –.–,–.– | C29: – | D29: – | U29: – | V29: –
A30: =_xlfn.CONCAT($A$2, ".", '$STRUCT'!$A28) -> FS.0.25 | B30: =_xlfn.CONCAT($C30,".",$D30,",",$U30,".",$V30) -> –.–,–.– | C30: – | D30: – | U30: – | V30: –
A31: =_xlfn.CONCAT($A$2, ".", '$STRUCT'!$A29) -> FS.0.26 | B31: =_xlfn.CONCAT($C31,".",$D31,",",$U31,".",$V31) -> –.–,–.– | C31: – | D31: – | U31: – | V31: –
A32: =_xlfn.CONCAT($A$2, ".", '$STRUCT'!$A30) -> FS.0.27 | B32: =_xlfn.CONCAT($C32,".",$D32,",",$U32,".",$V32) -> –.–,–.– | C32: – | D32: – | U32: – | V32: –
A33: =_xlfn.CONCAT($A$2, ".", '$STRUCT'!$A31) -> FS.0.28 | B33: =_xlfn.CONCAT($C33,".",$D33,",",$U33,".",$V33) -> –.–,–.– | C33: – | D33: – | U33: – | V33: –
... A45: =_xlfn.CONCAT($A$2, ".", '$STRUCT'!$A43) -> FS.0.40 | B45: =_xlfn.CONCAT($C45,".",$D45,",",$U45,".",$V45) -> –.–,–.– | C45: – | D45: – | U45: – | V45: –
A46: – | B46: =_xlfn.CONCAT($C46,".",$D46,",",$U46,".",$V46) -> –.–,–.– | C46: – | D46: – | E46: – | F46: 0 | G46: 1 | H46: 2 | I46: 3 | J46: 4 | K46: 5 | L46: – | M46: – | N46: 0 | O46: 1 | P46: 2 | Q46: 3 | R46: 4 | S46: 5 | T46: – | U46: – | V46: –

Sheet DYNAMIC.106
A1: VERS
A2: FS.0 | B2: /development/processes/index.js
A3: SEXTER | C3: LEXTER | N3: DEXTER
A4: VZD | B4: NEXTER | C4: SCOPID | D4: BLOKID | E4: SER | F4: TEN | M4: SYM | N4: SER | O4: TEN | V4: SYM | W4: SCOPID | X4: BLOKID
A5: ='$STRUCT'!$A3 -> 0 | B5: =_xlfn.CONCAT($A5,":",$C5,".",$D5,",",$W5,".",$X5) -> 0:0.0,0.0 | C5: 0 | D5: 0 | E5: class | F5: Processes | N5: extends | O5: Core | V5: {} | W5: 0 | X5: 0
A6: ='$STRUCT'!$A4 -> 1 | B6: =_xlfn.CONCAT($A6,":",$C6,".",$D6,",",$W6,".",$X6) -> 1:1.0,1.0 | C6: 1 | D6: 0 | G6: length | M6: = | O6: 0 | W6: 1 | X6: 0
A7: ='$STRUCT'!$A5 -> 2 | B7: =_xlfn.CONCAT($A7,":",$C7,".",$D7,",",$W7,".",$X7) -> 2:1.1,1.1 | C7: 1 | D7: 1 | G7: #parent | W7: 1 | X7: 1
A8: ='$STRUCT'!$A6 -> 3 | B8: =_xlfn.CONCAT($A8,":",$C8,".",$D8,",",$W8,".",$X8) -> 3:1.2,1.2 | C8: 1 | D8: 2 | G8: #source | W8: 1 | X8: 2
A9: ='$STRUCT'!$A7 -> 4 | B9: =_xlfn.CONCAT($A9,":",$C9,".",$D9,",",$W9,".",$X9) -> 4:1.3,1.3 | C9: 1 | D9: 3 | G9: #target | W9: 1 | X9: 3
